Workbook

Sheet Start here
A1: AkhiSal Excel toolkit
A2: Nothing to install. Open the file, type in the yellow cells, read the grey ones.
A5: Sheet | B5: What it is for
A6: Client Matcher | B6: Paste a list of client names in any spelling - Latin or Cyrillic - and get the matching CRM client, their phone, and a warning when several clients share that name.
A7: CRM Clients | B7: The reference list the matcher looks against: 50 clients copied from the CRM on 2026-09-19. Replace it with a fresh export whenever you like; the formulas follow.
A8: Phone Cleaner | B8: Paste phone numbers written any which way and get them back as 998XXXXXXXXX, ready for the CRM.
A9: Receivables | B9: Who owes what and for how long, bucketed 0-30 / 31-60 / 61-90 / 90+ days. Pre-filled with real unpaid orders.
A10: Money in Words | B10: Turn an amount into Uzbek words for invoices and contracts: 13 500 000 -> o'n uch million besh yuz ming so'm.
A12: Colour | B12: Meaning
A13: Yellow cell, blue text | B13: You type here. Everything else recalculates on its own.
A14: Grey cell, black text | B14: A formula. Leave it alone - or copy it down if you add rows.
A15: Pink cell | B15: Something needs a human eye.
A17: Built with classic Excel functions only, so it works in any Excel version and needs no macros, no add-in and no admin rights.

Sheet CRM Clients
A1: CRM Clients
A2: Reference list for the matcher. Snapshot taken 2026-09-19 - paste a fresh export over rows 4 and below any time.
A3: Client name | B3: Phone | C3: Address | D3: Name, normalised | E3: Clients sharing this name
A4: 0424 | B4: 998979740424 | C4: Андижон вилояти, Жалақудуқ тумани | D4: =TRIM(SUBSTITUTE(SUBSTITUTE(SUBSTITUTE(SUBSTITUTE(SUBSTITUTE(SUBSTITUTE(SUBSTITUTE(SUBSTITUTE(SUBSTITUTE(SUBSTITUTE(SUBSTITUTE(SUBSTITUTE(SUBSTITUTE(SUBSTITUTE(SUBSTITUTE(SUBSTITUTE(SUBSTITUTE(SUBSTITUTE(SUBSTITUTE(SUBSTITUTE(SUBSTITUTE(SUBSTITUTE(SUBSTITUTE(SUBSTITUTE(SUBSTITUTE(SUBSTITUTE(SUBSTITUTE(SUBSTITUTE(SUBSTITUTE(SUBSTITUTE(SUBSTITUTE(SUBSTITUTE(SUBSTITUTE(SUBSTITUTE(SUBSTITUTE(SUBSTITUTE(SUBSTITUTE(SUBSTITUTE(SUBSTITUTE(SUBSTITUTE(SUBSTITUTE(SUBSTITUTE(SUBSTITUTE(LOWER($A4),"ё","yo"),"ю","yu"),"я","ya"),"ц","ts"),"ч","ch"),"ш","sh"),"щ","sh"),"ў","o"),"қ","q"),"ғ","g"),"ҳ","h"),"а","a"),"б","b"),"в","v"),"г","g"),"д","d"),"е","e"),"ж","j"),"з","z"),"и","i"),"й","y"),"к","k"),"л","l"),"м","m"),"н","n"),"о","o"),"п","p"),"р","r"),"с","s"),"т","t"),"у","u"),"ф","f"),"х","x"),"ъ",""),"ы","i"),"ь",""),"э","e"),"'",""),"‘",""),"’",""),"ʻ",""),"ʼ",""),"`","")) | E4: =COUNTIF($D$4:$D$53,$D4)
A5: 28476 | B5: 998997919206 | C5: Farg‘ona viloyati, Quvasoy shahri | D5: =TRIM(SUBSTITUTE(SUBSTITUTE(SUBSTITUTE(SUBSTITUTE(SUBSTITUTE(SUBSTITUTE(SUBSTITUTE(SUBSTITUTE(SUBSTITUTE(SUBSTITUTE(SUBSTITUTE(SUBSTITUTE(SUBSTITUTE(SUBSTITUTE(SUBSTITUTE(SUBSTITUTE(SUBSTITUTE(SUBSTITUTE(SUBSTITUTE(SUBSTITUTE(SUBSTITUTE(SUBSTITUTE(SUBSTITUTE(SUBSTITUTE(SUBSTITUTE(SUBSTITUTE(SUBSTITUTE(SUBSTITUTE(SUBSTITUTE(SUBSTITUTE(SUBSTITUTE(SUBSTITUTE(SUBSTITUTE(SUBSTITUTE(SUBSTITUTE(SUBSTITUTE(SUBSTITUTE(SUBSTITUTE(SUBSTITUTE(SUBSTITUTE(SUBSTITUTE(SUBSTITUTE(SUBSTITUTE(LOWER($A5),"ё","yo"),"ю","yu"),"я","ya"),"ц","ts"),"ч","ch"),"ш","sh"),"щ","sh"),"ў","o"),"қ","q"),"ғ","g"),"ҳ","h"),"а","a"),"б","b"),"в","v"),"г","g"),"д","d"),"е","e"),"ж","j"),"з","z"),"и","i"),"й","y"),"к","k"),"л","l"),"м","m"),"н","n"),"о","o"),"п","p"),"р","r"),"с","s"),"т","t"),"у","u"),"ф","f"),"х","x"),"ъ",""),"ы","i"),"ь",""),"э","e"),"'",""),"‘",""),"’",""),"ʻ",""),"ʼ",""),"`","")) | E5: =COUNTIF($D$4:$D$53,$D5)
A6: 3050 | B6: 998508033050 | C6: Наманган вилояти, Наманган шаҳри | D6: =TRIM(SUBSTITUTE(SUBSTITUTE(SUBSTITUTE(SUBSTITUTE(SUBSTITUTE(SUBSTITUTE(SUBSTITUTE(SUBSTITUTE(SUBSTITUTE(SUBSTITUTE(SUBSTITUTE(SUBSTITUTE(SUBSTITUTE(SUBSTITUTE(SUBSTITUTE(SUBSTITUTE(SUBSTITUTE(SUBSTITUTE(SUBSTITUTE(SUBSTITUTE(SUBSTITUTE(SUBSTITUTE(SUBSTITUTE(SUBSTITUTE(SUBSTITUTE(SUBSTITUTE(SUBSTITUTE(SUBSTITUTE(SUBSTITUTE(SUBSTITUTE(SUBSTITUTE(SUBSTITUTE(SUBSTITUTE(SUBSTITUTE(SUBSTITUTE(SUBSTITUTE(SUBSTITUTE(SUBSTITUTE(SUBSTITUTE(SUBSTITUTE(SUBSTITUTE(SUBSTITUTE(SUBSTITUTE(LOWER($A6),"ё","yo"),"ю","yu"),"я","ya"),"ц","ts"),"ч","ch"),"ш","sh"),"щ","sh"),"ў","o"),"қ","q"),"ғ","g"),"ҳ","h"),"а","a"),"б","b"),"в","v"),"г","g"),"д","d"),"е","e"),"ж","j"),"з","z"),"и","i"),"й","y"),"к","k"),"л","l"),"м","m"),"н","n"),"о","o"),"п","p"),"р","r"),"с","s"),"т","t"),"у","u"),"ф","f"),"х","x"),"ъ",""),"ы","i"),"ь",""),"э","e"),"'",""),"‘",""),"’",""),"ʻ",""),"ʼ",""),"`","")) | E6: =COUNTIF($D$4:$D$53,$D6)
A7: 4455 | B7: 998917114455 | C7: Фарғона вилояти, Ўзбекистон тумани, Нурсух кишлоги | D7: =TRIM(SUBSTITUTE(SUBSTITUTE(SUBSTITUTE(SUBSTITUTE(SUBSTITUTE(SUBSTITUTE(SUBSTITUTE(SUBSTITUTE(SUBSTITUTE(SUBSTITUTE(SUBSTITUTE(SUBSTITUTE(SUBSTITUTE(SUBSTITUTE(SUBSTITUTE(SUBSTITUTE(SUBSTITUTE(SUBSTITUTE(SUBSTITUTE(SUBSTITUTE(SUBSTITUTE(SUBSTITUTE(SUBSTITUTE(SUBSTITUTE(SUBSTITUTE(SUBSTITUTE(SUBSTITUTE(SUBSTITUTE(SUBSTITUTE(SUBSTITUTE(SUBSTITUTE(SUBSTITUTE(SUBSTITUTE(SUBSTITUTE(SUBSTITUTE(SUBSTITUTE(SUBSTITUTE(SUBSTITUTE(SUBSTITUTE(SUBSTITUTE(SUBSTITUTE(SUBSTITUTE(SUBSTITUTE(LOWER($A7),"ё","yo"),"ю","yu"),"я","ya"),"ц","ts"),"ч","ch"),"ш","sh"),"щ","sh"),"ў","o"),"қ","q"),"ғ","g"),"ҳ","h"),"а","a"),"б","b"),"в","v"),"г","g"),"д","d"),"е","e"),"ж","j"),"з","z"),"и","i"),"й","y"),"к","k"),"л","l"),"м","m"),"н","n"),"о","o"),"п","p"),"р","r"),"с","s"),"т","t"),"у","u"),"ф","f"),"х","x"),"ъ",""),"ы","i"),"ь",""),"э","e"),"'",""),"‘",""),"’",""),"ʻ",""),"ʼ",""),"`","")) | E7: =COUNTIF($D$4:$D$53,$D7)
A8: 7004 | B8: 998934287004 | C8: Наманган вилояти, Учқўрғон тумани, Бозор боши | D8: =TRIM(SUBSTITUTE(SUBSTITUTE(SUBSTITUTE(SUBSTITUTE(SUBSTITUTE(SUBSTITUTE(SUBSTITUTE(SUBSTITUTE(SUBSTITUTE(SUBSTITUTE(SUBSTITUTE(SUBSTITUTE(SUBSTITUTE(SUBSTITUTE(SUBSTITUTE(SUBSTITUTE(SUBSTITUTE(SUBSTITUTE(SUBSTITUTE(SUBSTITUTE(SUBSTITUTE(SUBSTITUTE(SUBSTITUTE(SUBSTITUTE(SUBSTITUTE(SUBSTITUTE(SUBSTITUTE(SUBSTITUTE(SUBSTITUTE(SUBSTITUTE(SUBSTITUTE(SUBSTITUTE(SUBSTITUTE(SUBSTITUTE(SUBSTITUTE(SUBSTITUTE(SUBSTITUTE(SUBSTITUTE(SUBSTITUTE(SUBSTITUTE(SUBSTITUTE(SUBSTITUTE(SUBSTITUTE(LOWER($A8),"ё","yo"),"ю","yu"),"я","ya"),"ц","ts"),"ч","ch"),"ш","sh"),"щ","sh"),"ў","o"),"қ","q"),"ғ","g"),"ҳ","h"),"а","a"),"б","b"),"в","v"),"г","g"),"д","d"),"е","e"),"ж","j"),"з","z"),"и","i"),"й","y"),"к","k"),"л","l"),"м","m"),"н","n"),"о","o"),"п","p"),"р","r"),"с","s"),"т","t"),"у","u"),"ф","f"),"х","x"),"ъ",""),"ы","i"),"ь",""),"э","e"),"'",""),"‘",""),"’",""),"ʻ",""),"ʼ",""),"`","")) | E8: =COUNTIF($D$4:$D$53,$D8)
A9: 7272 | B9: 998918087272 | C9: Андижон вилояти, Шаҳрихон тумани | D9: =TRIM(SUBSTITUTE(SUBSTITUTE(SUBSTITUTE(SUBSTITUTE(SUBSTITUTE(SUBSTITUTE(SUBSTITUTE(SUBSTITUTE(SUBSTITUTE(SUBSTITUTE(SUBSTITUTE(SUBSTITUTE(SUBSTITUTE(SUBSTITUTE(SUBSTITUTE(SUBSTITUTE(SUBSTITUTE(SUBSTITUTE(SUBSTITUTE(SUBSTITUTE(SUBSTITUTE(SUBSTITUTE(SUBSTITUTE(SUBSTITUTE(SUBSTITUTE(SUBSTITUTE(SUBSTITUTE(SUBSTITUTE(SUBSTITUTE(SUBSTITUTE(SUBSTITUTE(SUBSTITUTE(SUBSTITUTE(SUBSTITUTE(SUBSTITUTE(SUBSTITUTE(SUBSTITUTE(SUBSTITUTE(SUBSTITUTE(SUBSTITUTE(SUBSTITUTE(SUBSTITUTE(SUBSTITUTE(LOWER($A9),"ё","yo"),"ю","yu"),"я","ya"),"ц","ts"),"ч","ch"),"ш","sh"),"щ","sh"),"ў","o"),"қ","q"),"ғ","g"),"ҳ","h"),"а","a"),"б","b"),"в","v"),"г","g"),"д","d"),"е","e"),"ж","j"),"з","z"),"и","i"),"й","y"),"к","k"),"л","l"),"м","m"),"н","n"),"о","o"),"п","p"),"р","r"),"с","s"),"т","t"),"у","u"),"ф","f"),"х","x"),"ъ",""),"ы","i"),"ь",""),"э","e"),"'",""),"‘",""),"’",""),"ʻ",""),"ʼ",""),"`","")) | E9: =COUNTIF($D$4:$D$53,$D9)
A10: @Alibek_1985 | B10: 998946028788 | C10: Тошкент вилояти, Янгийўл шаҳри | D10: =TRIM(SUBSTITUTE(SUBSTITUTE(SUBSTITUTE(SUBSTITUTE(SUBSTITUTE(SUBSTITUTE(SUBSTITUTE(SUBSTITUTE(SUBSTITUTE(SUBSTITUTE(SUBSTITUTE(SUBSTITUTE(SUBSTITUTE(SUBSTITUTE(SUBSTITUTE(SUBSTITUTE(SUBSTITUTE(SUBSTITUTE(SUBSTITUTE(SUBSTITUTE(SUBSTITUTE(SUBSTITUTE(SUBSTITUTE(SUBSTITUTE(SUBSTITUTE(SUBSTITUTE(SUBSTITUTE(SUBSTITUTE(SUBSTITUTE(SUBSTITUTE(SUBSTITUTE(SUBSTITUTE(SUBSTITUTE(SUBSTITUTE(SUBSTITUTE(SUBSTITUTE(SUBSTITUTE(SUBSTITUTE(SUBSTITUTE(SUBSTITUTE(SUBSTITUTE(SUBSTITUTE(SUBSTITUTE(LOWER($A10),"ё","yo"),"ю","yu"),"я","ya"),"ц","ts"),"ч","ch"),"ш","sh"),"щ","sh"),"ў","o"),"қ","q"),"ғ","g"),"ҳ","h"),"а","a"),"б","b"),"в","v"),"г","g"),"д","d"),"е","e"),"ж","j"),"з","z"),"и","i"),"й","y"),"к","k"),"л","l"),"м","m"),"н","n"),"о","o"),"п","p"),"р","r"),"с","s"),"т","t"),"у","u"),"ф","f"),"х","x"),"ъ",""),"ы","i"),"ь",""),"э","e"),"'",""),"‘",""),"’",""),"ʻ",""),"ʼ",""),"`","")) | E10: =COUNTIF($D$4:$D$53,$D10)
A11: AXADJON MO'YDINOV "IPEKCI_textile" | B11: 998993991105 | C11: Наманган вилояти, Чортоқ тумани | D11: =TRIM(SUBSTITUTE(SUBSTITUTE(SUBSTITUTE(SUBSTITUTE(SUBSTITUTE(SUBSTITUTE(SUBSTITUTE(SUBSTITUTE(SUBSTITUTE(SUBSTITUTE(SUBSTITUTE(SUBSTITUTE(SUBSTITUTE(SUBSTITUTE(SUBSTITUTE(SUBSTITUTE(SUBSTITUTE(SUBSTITUTE(SUBSTITUTE(SUBSTITUTE(SUBSTITUTE(SUBSTITUTE(SUBSTITUTE(SUBSTITUTE(SUBSTITUTE(SUBSTITUTE(SUBSTITUTE(SUBSTITUTE(SUBSTITUTE(SUBSTITUTE(SUBSTITUTE(SUBSTITUTE(SUBSTITUTE(SUBSTITUTE(SUBSTITUTE(SUBSTITUTE(SUBSTITUTE(SUBSTITUTE(SUBSTITUTE(SUBSTITUTE(SUBSTITUTE(SUBSTITUTE(SUBSTITUTE(LOWER($A11),"ё","yo"),"ю","yu"),"я","ya"),"ц","ts"),"ч","ch"),"ш","sh"),"щ","sh"),"ў","o"),"қ","q"),"ғ","g"),"ҳ","h"),"а","a"),"б","b"),"в","v"),"г","g"),"д","d"),"е","e"),"ж","j"),"з","z"),"и","i"),"й","y"),"к","k"),"л","l"),"м","m"),"н","n"),"о","o"),"п","p"),"р","r"),"с","s"),"т","t"),"у","u"),"ф","f"),"х","x"),"ъ",""),"ы","i"),"ь",""),"э","e"),"'",""),"‘",""),"’",""),"ʻ",""),"ʼ",""),"`","")) | E11: =COUNTIF($D$4:$D$53,$D11)
A12: Abdubanno | B12: 998958722624 | C12: Наманган вилояти, Янгиқўрғон тумани, Бирлашган | D12: =TRIM(SUBSTITUTE(SUBSTITUTE(SUBSTITUTE(SUBSTITUTE(SUBSTITUTE(SUBSTITUTE(SUBSTITUTE(SUBSTITUTE(SUBSTITUTE(SUBSTITUTE(SUBSTITUTE(SUBSTITUTE(SUBSTITUTE(SUBSTITUTE(SUBSTITUTE(SUBSTITUTE(SUBSTITUTE(SUBSTITUTE(SUBSTITUTE(SUBSTITUTE(SUBSTITUTE(SUBSTITUTE(SUBSTITUTE(SUBSTITUTE(SUBSTITUTE(SUBSTITUTE(SUBSTITUTE(SUBSTITUTE(SUBSTITUTE(SUBSTITUTE(SUBSTITUTE(SUBSTITUTE(SUBSTITUTE(SUBSTITUTE(SUBSTITUTE(SUBSTITUTE(SUBSTITUTE(SUBSTITUTE(SUBSTITUTE(SUBSTITUTE(SUBSTITUTE(SUBSTITUTE(SUBSTITUTE(LOWER($A12),"ё","yo"),"ю","yu"),"я","ya"),"ц","ts"),"ч","ch"),"ш","sh"),"щ","sh"),"ў","o"),"қ","q"),"ғ","g"),"ҳ","h"),"а","a"),"б","b"),"в","v"),"г","g"),"д","d"),"е","e"),"ж","j"),"з","z"),"и","i"),"й","y"),"к","k"),"л","l"),"м","m"),"н","n"),"о","o"),"п","p"),"р","r"),"с","s"),"т","t"),"у","u"),"ф","f"),"х","x"),"ъ",""),"ы","i"),"ь",""),"э","e"),"'",""),"‘",""),"’",""),"ʻ",""),"ʼ",""),"`","")) | E12: =COUNTIF($D$4:$D$53,$D12)
A13: Abdujalil | B13: 998975721101 | C13: Begovot | D13: =TRIM(SUBSTITUTE(SUBSTITUTE(SUBSTITUTE(SUBSTITUTE(SUBSTITUTE(SUBSTITUTE(SUBSTITUTE(SUBSTITUTE(SUBSTITUTE(SUBSTITUTE(SUBSTITUTE(SUBSTITUTE(SUBSTITUTE(SUBSTITUTE(SUBSTITUTE(SUBSTITUTE(SUBSTITUTE(SUBSTITUTE(SUBSTITUTE(SUBSTITUTE(SUBSTITUTE(SUBSTITUTE(SUBSTITUTE(SUBSTITUTE(SUBSTITUTE(SUBSTITUTE(SUBSTITUTE(SUBSTITUTE(SUBSTITUTE(SUBSTITUTE(SUBSTITUTE(SUBSTITUTE(SUBSTITUTE(SUBSTITUTE(SUBSTITUTE(SUBSTITUTE(SUBSTITUTE(SUBSTITUTE(SUBSTITUTE(SUBSTITUTE(SUBSTITUTE(SUBSTITUTE(SUBSTITUTE(LOWER($A13),"ё","yo"),"ю","yu"),"я","ya"),"ц","ts"),"ч","ch"),"ш","sh"),"щ","sh"),"ў","o"),"қ","q"),"ғ","g"),"ҳ","h"),"а","a"),"б","b"),"в","v"),"г","g"),"д","d"),"е","e"),"ж","j"),"з","z"),"и","i"),"й","y"),"к","k"),"л","l"),"м","m"),"н","n"),"о","o"),"п","p"),"р","r"),"с","s"),"т","t"),"у","u"),"ф","f"),"х","x"),"ъ",""),"ы","i"),"ь",""),"э","e"),"'",""),"‘",""),"’",""),"ʻ",""),"ʼ",""),"`","")) | E13: =COUNTIF($D$4:$D$53,$D13)
A14: Abdukulov | B14: 998991876227 | C14: Тошкент вилояти, Оҳангарон тумани | D14: =TRIM(SUBSTITUTE(SUBSTITUTE(SUBSTITUTE(SUBSTITUTE(SUBSTITUTE(SUBSTITUTE(SUBSTITUTE(SUBSTITUTE(SUBSTITUTE(SUBSTITUTE(SUBSTITUTE(SUBSTITUTE(SUBSTITUTE(SUBSTITUTE(SUBSTITUTE(SUBSTITUTE(SUBSTITUTE(SUBSTITUTE(SUBSTITUTE(SUBSTITUTE(SUBSTITUTE(SUBSTITUTE(SUBSTITUTE(SUBSTITUTE(SUBSTITUTE(SUBSTITUTE(SUBSTITUTE(SUBSTITUTE(SUBSTITUTE(SUBSTITUTE(SUBSTITUTE(SUBSTITUTE(SUBSTITUTE(SUBSTITUTE(SUBSTITUTE(SUBSTITUTE(SUBSTITUTE(SUBSTITUTE(SUBSTITUTE(SUBSTITUTE(SUBSTITUTE(SUBSTITUTE(SUBSTITUTE(LOWER($A14),"ё","yo"),"ю","yu"),"я","ya"),"ц","ts"),"ч","ch"),"ш","sh"),"щ","sh"),"ў","o"),"қ","q"),"ғ","g"),"ҳ","h"),"а","a"),"б","b"),"в","v"),"г","g"),"д","d"),"е","e"),"ж","j"),"з","z"),"и","i"),"й","y"),"к","k"),"л","l"),"м","m"),"н","n"),"о","o"),"п","p"),"р","r"),"с","s"),"т","t"),"у","u"),"ф","f"),"х","x"),"ъ",""),"ы","i"),"ь",""),"э","e"),"'",""),"‘",""),"’",""),"ʻ",""),"ʼ",""),"`","")) | E14: =COUNTIF($D$4:$D$53,$D14)
A15: Abdulahad Chinaqov | B15: 998930546090 | C15: Наманган вилояти, Тўрақўрғон тумани | D15: =TRIM(SUBSTITUTE(SUBSTITUTE(SUBSTITUTE(SUBSTITUTE(SUBSTITUTE(SUBSTITUTE(SUBSTITUTE(SUBSTITUTE(SUBSTITUTE(SUBSTITUTE(SUBSTITUTE(SUBSTITUTE(SUBSTITUTE(SUBSTITUTE(SUBSTITUTE(SUBSTITUTE(SUBSTITUTE(SUBSTITUTE(SUBSTITUTE(SUBSTITUTE(SUBSTITUTE(SUBSTITUTE(SUBSTITUTE(SUBSTITUTE(SUBSTITUTE(SUBSTITUTE(SUBSTITUTE(SUBSTITUTE(SUBSTITUTE(SUBSTITUTE(SUBSTITUTE(SUBSTITUTE(SUBSTITUTE(SUBSTITUTE(SUBSTITUTE(SUBSTITUTE(SUBSTITUTE(SUBSTITUTE(SUBSTITUTE(SUBSTITUTE(SUBSTITUTE(SUBSTITUTE(SUBSTITUTE(LOWER($A15),"ё","yo"),"ю","yu"),"я","ya"),"ц","ts"),"ч","ch"),"ш","sh"),"щ","sh"),"ў","o"),"қ","q"),"ғ","g"),"ҳ","h"),"а","a"),"б","b"),"в","v"),"г","g"),"д","d"),"е","e"),"ж","j"),"з","z"),"и","i"),"й","y"),"к","k"),"л","l"),"м","m"),"н","n"),"о","o"),"п","p"),"р","r"),"с","s"),"т","t"),"у","u"),"ф","f"),"х","x"),"ъ",""),"ы","i"),"ь",""),"э","e"),"'",""),"‘",""),"’",""),"ʻ",""),"ʼ",""),"`","")) | E15: =COUNTIF($D$4:$D$53,$D15)
... A53: Davron Vahobov | B53: 998941575550 | C53: Namangan, Chorsu | D53: =TRIM(SUBSTITUTE(SUBSTITUTE(SUBSTITUTE(SUBSTITUTE(SUBSTITUTE(SUBSTITUTE(SUBSTITUTE(SUBSTITUTE(SUBSTITUTE(SUBSTITUTE(SUBSTITUTE(SUBSTITUTE(SUBSTITUTE(SUBSTITUTE(SUBSTITUTE(SUBSTITUTE(SUBSTITUTE(SUBSTITUTE(SUBSTITUTE(SUBSTITUTE(SUBSTITUTE(SUBSTITUTE(SUBSTITUTE(SUBSTITUTE(SUBSTITUTE(SUBSTITUTE(SUBSTITUTE(SUBSTITUTE(SUBSTITUTE(SUBSTITUTE(SUBSTITUTE(SUBSTITUTE(SUBSTITUTE(SUBSTITUTE(SUBSTITUTE(SUBSTITUTE(SUBSTITUTE(SUBSTITUTE(SUBSTITUTE(SUBSTITUTE(SUBSTITUTE(SUBSTITUTE(SUBSTITUTE(LOWER($A53),"ё","yo"),"ю","yu"),"я","ya"),"ц","ts"),"ч","ch"),"ш","sh"),"щ","sh"),"ў","o"),"қ","q"),"ғ","g"),"ҳ","h"),"а","a"),"б","b"),"в","v"),"г","g"),"д","d"),"е","e"),"ж","j"),"з","z"),"и","i"),"й","y"),"к","k"),"л","l"),"м","m"),"н","n"),"о","o"),"п","p"),"р","r"),"с","s"),"т","t"),"у","u"),"ф","f"),"х","x"),"ъ",""),"ы","i"),"ь",""),"э","e"),"'",""),"‘",""),"’",""),"ʻ",""),"ʼ",""),"`","")) | E53: =COUNTIF($D$4:$D$53,$D53)

Sheet Client Matcher
A1: Client Matcher
A2: Type or paste names into the yellow column. Latin or Cyrillic, either works.
A3: Name as you have it | B3: Normalised | C3: Matching CRM client | D3: Phone | E3: Result | F3: Matches
A4: Халимжон | B4: =IF($A4="","",TRIM(SUBSTITUTE(SUBSTITUTE(SUBSTITUTE(SUBSTITUTE(SUBSTITUTE(SUBSTITUTE(SUBSTITUTE(SUBSTITUTE(SUBSTITUTE(SUBSTITUTE(SUBSTITUTE(SUBSTITUTE(SUBSTITUTE(SUBSTITUTE(SUBSTITUTE(SUBSTITUTE(SUBSTITUTE(SUBSTITUTE(SUBSTITUTE(SUBSTITUTE(SUBSTITUTE(SUBSTITUTE(SUBSTITUTE(SUBSTITUTE(SUBSTITUTE(SUBSTITUTE(SUBSTITUTE(SUBSTITUTE(SUBSTITUTE(SUBSTITUTE(SUBSTITUTE(SUBSTITUTE(SUBSTITUTE(SUBSTITUTE(SUBSTITUTE(SUBSTITUTE(SUBSTITUTE(SUBSTITUTE(SUBSTITUTE(SUBSTITUTE(SUBSTITUTE(SUBSTITUTE(SUBSTITUTE(LOWER($A4),"ё","yo"),"ю","yu"),"я","ya"),"ц","ts"),"ч","ch"),"ш","sh"),"щ","sh"),"ў","o"),"қ","q"),"ғ","g"),"ҳ","h"),"а","a"),"б","b"),"в","v"),"г","g"),"д","d"),"е","e"),"ж","j"),"з","z"),"и","i"),"й","y"),"к","k"),"л","l"),"м","m"),"н","n"),"о","o"),"п","p"),"р","r"),"с","s"),"т","t"),"у","u"),"ф","f"),"х","x"),"ъ",""),"ы","i"),"ь",""),"э","e"),"'",""),"‘",""),"’",""),"ʻ",""),"ʼ",""),"`",""))) | C4: =IF($B4="","",IFERROR(INDEX('CRM Clients'!$A$4:$A$53,MATCH($B4,'CRM Clients'!$D$4:$D$53,0)),"not found")) | D4: =IF($B4="","",IFERROR(INDEX('CRM Clients'!$B$4:$B$53,MATCH($B4,'CRM Clients'!$D$4:$D$53,0)),"")) | E4: =IF($B4="","",IF($F4=0,"no match - new client, or a typo",IF($F4>1,"CHECK PHONE - "&$F4&" clients share this name","matched"))) | F4: =IF($B4="","",COUNTIF('CRM Clients'!$D$4:$D$53,$B4))
A5: ШУҲРАТЖОН АКА | B5: =IF($A5="","",TRIM(SUBSTITUTE(SUBSTITUTE(SUBSTITUTE(SUBSTITUTE(SUBSTITUTE(SUBSTITUTE(SUBSTITUTE(SUBSTITUTE(SUBSTITUTE(SUBSTITUTE(SUBSTITUTE(SUBSTITUTE(SUBSTITUTE(SUBSTITUTE(SUBSTITUTE(SUBSTITUTE(SUBSTITUTE(SUBSTITUTE(SUBSTITUTE(SUBSTITUTE(SUBSTITUTE(SUBSTITUTE(SUBSTITUTE(SUBSTITUTE(SUBSTITUTE(SUBSTITUTE(SUBSTITUTE(SUBSTITUTE(SUBSTITUTE(SUBSTITUTE(SUBSTITUTE(SUBSTITUTE(SUBSTITUTE(SUBSTITUTE(SUBSTITUTE(SUBSTITUTE(SUBSTITUTE(SUBSTITUTE(SUBSTITUTE(SUBSTITUTE(SUBSTITUTE(SUBSTITUTE(SUBSTITUTE(LOWER($A5),"ё","yo"),"ю","yu"),"я","ya"),"ц","ts"),"ч","ch"),"ш","sh"),"щ","sh"),"ў","o"),"қ","q"),"ғ","g"),"ҳ","h"),"а","a"),"б","b"),"в","v"),"г","g"),"д","d"),"е","e"),"ж","j"),"з","z"),"и","i"),"й","y"),"к","k"),"л","l"),"м","m"),"н","n"),"о","o"),"п","p"),"р","r"),"с","s"),"т","t"),"у","u"),"ф","f"),"х","x"),"ъ",""),"ы","i"),"ь",""),"э","e"),"'",""),"‘",""),"’",""),"ʻ",""),"ʼ",""),"`",""))) | C5: =IF($B5="","",IFERROR(INDEX('CRM Clients'!$A$4:$A$53,MATCH($B5,'CRM Clients'!$D$4:$D$53,0)),"not found")) | D5: =IF($B5="","",IFERROR(INDEX('CRM Clients'!$B$4:$B$53,MATCH($B5,'CRM Clients'!$D$4:$D$53,0)),"")) | E5: =IF($B5="","",IF($F5=0,"no match - new client, or a typo",IF($F5>1,"CHECK PHONE - "&$F5&" clients share this name","matched"))) | F5: =IF($B5="","",COUNTIF('CRM Clients'!$D$4:$D$53,$B5))
A6: Abdulloh | B6: =IF($A6="","",TRIM(SUBSTITUTE(SUBSTITUTE(SUBSTITUTE(SUBSTITUTE(SUBSTITUTE(SUBSTITUTE(SUBSTITUTE(SUBSTITUTE(SUBSTITUTE(SUBSTITUTE(SUBSTITUTE(SUBSTITUTE(SUBSTITUTE(SUBSTITUTE(SUBSTITUTE(SUBSTITUTE(SUBSTITUTE(SUBSTITUTE(SUBSTITUTE(SUBSTITUTE(SUBSTITUTE(SUBSTITUTE(SUBSTITUTE(SUBSTITUTE(SUBSTITUTE(SUBSTITUTE(SUBSTITUTE(SUBSTITUTE(SUBSTITUTE(SUBSTITUTE(SUBSTITUTE(SUBSTITUTE(SUBSTITUTE(SUBSTITUTE(SUBSTITUTE(SUBSTITUTE(SUBSTITUTE(SUBSTITUTE(SUBSTITUTE(SUBSTITUTE(SUBSTITUTE(SUBSTITUTE(SUBSTITUTE(LOWER($A6),"ё","yo"),"ю","yu"),"я","ya"),"ц","ts"),"ч","ch"),"ш","sh"),"щ","sh"),"ў","o"),"қ","q"),"ғ","g"),"ҳ","h"),"а","a"),"б","b"),"в","v"),"г","g"),"д","d"),"е","e"),"ж","j"),"з","z"),"и","i"),"й","y"),"к","k"),"л","l"),"м","m"),"н","n"),"о","o"),"п","p"),"р","r"),"с","s"),"т","t"),"у","u"),"ф","f"),"х","x"),"ъ",""),"ы","i"),"ь",""),"э","e"),"'",""),"‘",""),"’",""),"ʻ",""),"ʼ",""),"`",""))) | C6: =IF($B6="","",IFERROR(INDEX('CRM Clients'!$A$4:$A$53,MATCH($B6,'CRM Clients'!$D$4:$D$53,0)),"not found")) | D6: =IF($B6="","",IFERROR(INDEX('CRM Clients'!$B$4:$B$53,MATCH($B6,'CRM Clients'!$D$4:$D$53,0)),"")) | E6: =IF($B6="","",IF($F6=0,"no match - new client, or a typo",IF($F6>1,"CHECK PHONE - "&$F6&" clients share this name","matched"))) | F6: =IF($B6="","",COUNTIF('CRM Clients'!$D$4:$D$53,$B6))
A7: Баходир | B7: =IF($A7="","",TRIM(SUBSTITUTE(SUBSTITUTE(SUBSTITUTE(SUBSTITUTE(SUBSTITUTE(SUBSTITUTE(SUBSTITUTE(SUBSTITUTE(SUBSTITUTE(SUBSTITUTE(SUBSTITUTE(SUBSTITUTE(SUBSTITUTE(SUBSTITUTE(SUBSTITUTE(SUBSTITUTE(SUBSTITUTE(SUBSTITUTE(SUBSTITUTE(SUBSTITUTE(SUBSTITUTE(SUBSTITUTE(SUBSTITUTE(SUBSTITUTE(SUBSTITUTE(SUBSTITUTE(SUBSTITUTE(SUBSTITUTE(SUBSTITUTE(SUBSTITUTE(SUBSTITUTE(SUBSTITUTE(SUBSTITUTE(SUBSTITUTE(SUBSTITUTE(SUBSTITUTE(SUBSTITUTE(SUBSTITUTE(SUBSTITUTE(SUBSTITUTE(SUBSTITUTE(SUBSTITUTE(SUBSTITUTE(LOWER($A7),"ё","yo"),"ю","yu"),"я","ya"),"ц","ts"),"ч","ch"),"ш","sh"),"щ","sh"),"ў","o"),"қ","q"),"ғ","g"),"ҳ","h"),"а","a"),"б","b"),"в","v"),"г","g"),"д","d"),"е","e"),"ж","j"),"з","z"),"и","i"),"й","y"),"к","k"),"л","l"),"м","m"),"н","n"),"о","o"),"п","p"),"р","r"),"с","s"),"т","t"),"у","u"),"ф","f"),"х","x"),"ъ",""),"ы","i"),"ь",""),"э","e"),"'",""),"‘",""),"’",""),"ʻ",""),"ʼ",""),"`",""))) | C7: =IF($B7="","",IFERROR(INDEX('CRM Clients'!$A$4:$A$53,MATCH($B7,'CRM Clients'!$D$4:$D$53,0)),"not found")) | D7: =IF($B7="","",IFERROR(INDEX('CRM Clients'!$B$4:$B$53,MATCH($B7,'CRM Clients'!$D$4:$D$53,0)),"")) | E7: =IF($B7="","",IF($F7=0,"no match - new client, or a typo",IF($F7>1,"CHECK PHONE - "&$F7&" clients share this name","matched"))) | F7: =IF($B7="","",COUNTIF('CRM Clients'!$D$4:$D$53,$B7))
A8: Davron Vahobov | B8: =IF($A8="","",TRIM(SUBSTITUTE(SUBSTITUTE(SUBSTITUTE(SUBSTITUTE(SUBSTITUTE(SUBSTITUTE(SUBSTITUTE(SUBSTITUTE(SUBSTITUTE(SUBSTITUTE(SUBSTITUTE(SUBSTITUTE(SUBSTITUTE(SUBSTITUTE(SUBSTITUTE(SUBSTITUTE(SUBSTITUTE(SUBSTITUTE(SUBSTITUTE(SUBSTITUTE(SUBSTITUTE(SUBSTITUTE(SUBSTITUTE(SUBSTITUTE(SUBSTITUTE(SUBSTITUTE(SUBSTITUTE(SUBSTITUTE(SUBSTITUTE(SUBSTITUTE(SUBSTITUTE(SUBSTITUTE(SUBSTITUTE(SUBSTITUTE(SUBSTITUTE(SUBSTITUTE(SUBSTITUTE(SUBSTITUTE(SUBSTITUTE(SUBSTITUTE(SUBSTITUTE(SUBSTITUTE(SUBSTITUTE(LOWER($A8),"ё","yo"),"ю","yu"),"я","ya"),"ц","ts"),"ч","ch"),"ш","sh"),"щ","sh"),"ў","o"),"қ","q"),"ғ","g"),"ҳ","h"),"а","a"),"б","b"),"в","v"),"г","g"),"д","d"),"е","e"),"ж","j"),"з","z"),"и","i"),"й","y"),"к","k"),"л","l"),"м","m"),"н","n"),"о","o"),"п","p"),"р","r"),"с","s"),"т","t"),"у","u"),"ф","f"),"х","x"),"ъ",""),"ы","i"),"ь",""),"э","e"),"'",""),"‘",""),"’",""),"ʻ",""),"ʼ",""),"`",""))) | C8: =IF($B8="","",IFERROR(INDEX('CRM Clients'!$A$4:$A$53,MATCH($B8,'CRM Clients'!$D$4:$D$53,0)),"not found")) | D8: =IF($B8="","",IFERROR(INDEX('CRM Clients'!$B$4:$B$53,MATCH($B8,'CRM Clients'!$D$4:$D$53,0)),"")) | E8: =IF($B8="","",IF($F8=0,"no match - new client, or a typo",IF($F8>1,"CHECK PHONE - "&$F8&" clients share this name","matched"))) | F8: =IF($B8="","",COUNTIF('CRM Clients'!$D$4:$D$53,$B8))
A9: Нематжон | B9: =IF($A9="","",TRIM(SUBSTITUTE(SUBSTITUTE(SUBSTITUTE(SUBSTITUTE(SUBSTITUTE(SUBSTITUTE(SUBSTITUTE(SUBSTITUTE(SUBSTITUTE(SUBSTITUTE(SUBSTITUTE(SUBSTITUTE(SUBSTITUTE(SUBSTITUTE(SUBSTITUTE(SUBSTITUTE(SUBSTITUTE(SUBSTITUTE(SUBSTITUTE(SUBSTITUTE(SUBSTITUTE(SUBSTITUTE(SUBSTITUTE(SUBSTITUTE(SUBSTITUTE(SUBSTITUTE(SUBSTITUTE(SUBSTITUTE(SUBSTITUTE(SUBSTITUTE(SUBSTITUTE(SUBSTITUTE(SUBSTITUTE(SUBSTITUTE(SUBSTITUTE(SUBSTITUTE(SUBSTITUTE(SUBSTITUTE(SUBSTITUTE(SUBSTITUTE(SUBSTITUTE(SUBSTITUTE(SUBSTITUTE(LOWER($A9),"ё","yo"),"ю","yu"),"я","ya"),"ц","ts"),"ч","ch"),"ш","sh"),"щ","sh"),"ў","o"),"қ","q"),"ғ","g"),"ҳ","h"),"а","a"),"б","b"),"в","v"),"г","g"),"д","d"),"е","e"),"ж","j"),"з","z"),"и","i"),"й","y"),"к","k"),"л","l"),"м","m"),"н","n"),"о","o"),"п","p"),"р","r"),"с","s"),"т","t"),"у","u"),"ф","f"),"х","x"),"ъ",""),"ы","i"),"ь",""),"э","e"),"'",""),"‘",""),"’",""),"ʻ",""),"ʼ",""),"`",""))) | C9: =IF($B9="","",IFERROR(INDEX('CRM Clients'!$A$4:$A$53,MATCH($B9,'CRM Clients'!$D$4:$D$53,0)),"not found")) | D9: =IF($B9="","",IFERROR(INDEX('CRM Clients'!$B$4:$B$53,MATCH($B9,'CRM Clients'!$D$4:$D$53,0)),"")) | E9: =IF($B9="","",IF($F9=0,"no match - new client, or a typo",IF($F9>1,"CHECK PHONE - "&$F9&" clients share this name","matched"))) | F9: =IF($B9="","",COUNTIF('CRM Clients'!$D$4:$D$53,$B9))
B10: =IF($A10="","",TRIM(SUBSTITUTE(SUBSTITUTE(SUBSTITUTE(SUBSTITUTE(SUBSTITUTE(SUBSTITUTE(SUBSTITUTE(SUBSTITUTE(SUBSTITUTE(SUBSTITUTE(SUBSTITUTE(SUBSTITUTE(SUBSTITUTE(SUBSTITUTE(SUBSTITUTE(SUBSTITUTE(SUBSTITUTE(SUBSTITUTE(SUBSTITUTE(SUBSTITUTE(SUBSTITUTE(SUBSTITUTE(SUBSTITUTE(SUBSTITUTE(SUBSTITUTE(SUBSTITUTE(SUBSTITUTE(SUBSTITUTE(SUBSTITUTE(SUBSTITUTE(SUBSTITUTE(SUBSTITUTE(SUBSTITUTE(SUBSTITUTE(SUBSTITUTE(SUBSTITUTE(SUBSTITUTE(SUBSTITUTE(SUBSTITUTE(SUBSTITUTE(SUBSTITUTE(SUBSTITUTE(SUBSTITUTE(LOWER($A10),"ё","yo"),"ю","yu"),"я","ya"),"ц","ts"),"ч","ch"),"ш","sh"),"щ","sh"),"ў","o"),"қ","q"),"ғ","g"),"ҳ","h"),"а","a"),"б","b"),"в","v"),"г","g"),"д","d"),"е","e"),"ж","j"),"з","z"),"и","i"),"й","y"),"к","k"),"л","l"),"м","m"),"н","n"),"о","o"),"п","p"),"р","r"),"с","s"),"т","t"),"у","u"),"ф","f"),"х","x"),"ъ",""),"ы","i"),"ь",""),"э","e"),"'",""),"‘",""),"’",""),"ʻ",""),"ʼ",""),"`",""))) | C10: =IF($B10="","",IFERROR(INDEX('CRM Clients'!$A$4:$A$53,MATCH($B10,'CRM Clients'!$D$4:$D$53,0)),"not found")) | D10: =IF($B10="","",IFERROR(INDEX('CRM Clients'!$B$4:$B$53,MATCH($B10,'CRM Clients'!$D$4:$D$53,0)),"")) | E10: =IF($B10="","",IF($F10=0,"no match - new client, or a typo",IF($F10>1,"CHECK PHONE - "&$F10&" clients share this name","matched"))) | F10: =IF($B10="","",COUNTIF('CRM Clients'!$D$4:$D$53,$B10))
B11: =IF($A11="","",TRIM(SUBSTITUTE(SUBSTITUTE(SUBSTITUTE(SUBSTITUTE(SUBSTITUTE(SUBSTITUTE(SUBSTITUTE(SUBSTITUTE(SUBSTITUTE(SUBSTITUTE(SUBSTITUTE(SUBSTITUTE(SUBSTITUTE(SUBSTITUTE(SUBSTITUTE(SUBSTITUTE(SUBSTITUTE(SUBSTITUTE(SUBSTITUTE(SUBSTITUTE(SUBSTITUTE(SUBSTITUTE(SUBSTITUTE(SUBSTITUTE(SUBSTITUTE(SUBSTITUTE(SUBSTITUTE(SUBSTITUTE(SUBSTITUTE(SUBSTITUTE(SUBSTITUTE(SUBSTITUTE(SUBSTITUTE(SUBSTITUTE(SUBSTITUTE(SUBSTITUTE(SUBSTITUTE(SUBSTITUTE(SUBSTITUTE(SUBSTITUTE(SUBSTITUTE(SUBSTITUTE(SUBSTITUTE(LOWER($A11),"ё","yo"),"ю","yu"),"я","ya"),"ц","ts"),"ч","ch"),"ш","sh"),"щ","sh"),"ў","o"),"қ","q"),"ғ","g"),"ҳ","h"),"а","a"),"б","b"),"в","v"),"г","g"),"д","d"),"е","e"),"ж","j"),"з","z"),"и","i"),"й","y"),"к","k"),"л","l"),"м","m"),"н","n"),"о","o"),"п","p"),"р","r"),"с","s"),"т","t"),"у","u"),"ф","f"),"х","x"),"ъ",""),"ы","i"),"ь",""),"э","e"),"'",""),"‘",""),"’",""),"ʻ",""),"ʼ",""),"`",""))) | C11: =IF($B11="","",IFERROR(INDEX('CRM Clients'!$A$4:$A$53,MATCH($B11,'CRM Clients'!$D$4:$D$53,0)),"not found")) | D11: =IF($B11="","",IFERROR(INDEX('CRM Clients'!$B$4:$B$53,MATCH($B11,'CRM Clients'!$D$4:$D$53,0)),"")) | E11: =IF($B11="","",IF($F11=0,"no match - new client, or a typo",IF($F11>1,"CHECK PHONE - "&$F11&" clients share this name","matched"))) | F11: =IF($B11="","",COUNTIF('CRM Clients'!$D$4:$D$53,$B11))
B12: =IF($A12="","",TRIM(SUBSTITUTE(SUBSTITUTE(SUBSTITUTE(SUBSTITUTE(SUBSTITUTE(SUBSTITUTE(SUBSTITUTE(SUBSTITUTE(SUBSTITUTE(SUBSTITUTE(SUBSTITUTE(SUBSTITUTE(SUBSTITUTE(SUBSTITUTE(SUBSTITUTE(SUBSTITUTE(SUBSTITUTE(SUBSTITUTE(SUBSTITUTE(SUBSTITUTE(SUBSTITUTE(SUBSTITUTE(SUBSTITUTE(SUBSTITUTE(SUBSTITUTE(SUBSTITUTE(SUBSTITUTE(SUBSTITUTE(SUBSTITUTE(SUBSTITUTE(SUBSTITUTE(SUBSTITUTE(SUBSTITUTE(SUBSTITUTE(SUBSTITUTE(SUBSTITUTE(SUBSTITUTE(SUBSTITUTE(SUBSTITUTE(SUBSTITUTE(SUBSTITUTE(SUBSTITUTE(SUBSTITUTE(LOWER($A12),"ё","yo"),"ю","yu"),"я","ya"),"ц","ts"),"ч","ch"),"ш","sh"),"щ","sh"),"ў","o"),"қ","q"),"ғ","g"),"ҳ","h"),"а","a"),"б","b"),"в","v"),"г","g"),"д","d"),"е","e"),"ж","j"),"з","z"),"и","i"),"й","y"),"к","k"),"л","l"),"м","m"),"н","n"),"о","o"),"п","p"),"р","r"),"с","s"),"т","t"),"у","u"),"ф","f"),"х","x"),"ъ",""),"ы","i"),"ь",""),"э","e"),"'",""),"‘",""),"’",""),"ʻ",""),"ʼ",""),"`",""))) | C12: =IF($B12="","",IFERROR(INDEX('CRM Clients'!$A$4:$A$53,MATCH($B12,'CRM Clients'!$D$4:$D$53,0)),"not found")) | D12: =IF($B12="","",IFERROR(INDEX('CRM Clients'!$B$4:$B$53,MATCH($B12,'CRM Clients'!$D$4:$D$53,0)),"")) | E12: =IF($B12="","",IF($F12=0,"no match - new client, or a typo",IF($F12>1,"CHECK PHONE - "&$F12&" clients share this name","matched"))) | F12: =IF($B12="","",COUNTIF('CRM Clients'!$D$4:$D$53,$B12))
B13: =IF($A13="","",TRIM(SUBSTITUTE(SUBSTITUTE(SUBSTITUTE(SUBSTITUTE(SUBSTITUTE(SUBSTITUTE(SUBSTITUTE(SUBSTITUTE(SUBSTITUTE(SUBSTITUTE(SUBSTITUTE(SUBSTITUTE(SUBSTITUTE(SUBSTITUTE(SUBSTITUTE(SUBSTITUTE(SUBSTITUTE(SUBSTITUTE(SUBSTITUTE(SUBSTITUTE(SUBSTITUTE(SUBSTITUTE(SUBSTITUTE(SUBSTITUTE(SUBSTITUTE(SUBSTITUTE(SUBSTITUTE(SUBSTITUTE(SUBSTITUTE(SUBSTITUTE(SUBSTITUTE(SUBSTITUTE(SUBSTITUTE(SUBSTITUTE(SUBSTITUTE(SUBSTITUTE(SUBSTITUTE(SUBSTITUTE(SUBSTITUTE(SUBSTITUTE(SUBSTITUTE(SUBSTITUTE(SUBSTITUTE(LOWER($A13),"ё","yo"),"ю","yu"),"я","ya"),"ц","ts"),"ч","ch"),"ш","sh"),"щ","sh"),"ў","o"),"қ","q"),"ғ","g"),"ҳ","h"),"а","a"),"б","b"),"в","v"),"г","g"),"д","d"),"е","e"),"ж","j"),"з","z"),"и","i"),"й","y"),"к","k"),"л","l"),"м","m"),"н","n"),"о","o"),"п","p"),"р","r"),"с","s"),"т","t"),"у","u"),"ф","f"),"х","x"),"ъ",""),"ы","i"),"ь",""),"э","e"),"'",""),"‘",""),"’",""),"ʻ",""),"ʼ",""),"`",""))) | C13: =IF($B13="","",IFERROR(INDEX('CRM Clients'!$A$4:$A$53,MATCH($B13,'CRM Clients'!$D$4:$D$53,0)),"not found")) | D13: =IF($B13="","",IFERROR(INDEX('CRM Clients'!$B$4:$B$53,MATCH($B13,'CRM Clients'!$D$4:$D$53,0)),"")) | E13: =IF($B13="","",IF($F13=0,"no match - new client, or a typo",IF($F13>1,"CHECK PHONE - "&$F13&" clients share this name","matched"))) | F13: =IF($B13="","",COUNTIF('CRM Clients'!$D$4:$D$53,$B13))
B14: =IF($A14="","",TRIM(SUBSTITUTE(SUBSTITUTE(SUBSTITUTE(SUBSTITUTE(SUBSTITUTE(SUBSTITUTE(SUBSTITUTE(SUBSTITUTE(SUBSTITUTE(SUBSTITUTE(SUBSTITUTE(SUBSTITUTE(SUBSTITUTE(SUBSTITUTE(SUBSTITUTE(SUBSTITUTE(SUBSTITUTE(SUBSTITUTE(SUBSTITUTE(SUBSTITUTE(SUBSTITUTE(SUBSTITUTE(SUBSTITUTE(SUBSTITUTE(SUBSTITUTE(SUBSTITUTE(SUBSTITUTE(SUBSTITUTE(SUBSTITUTE(SUBSTITUTE(SUBSTITUTE(SUBSTITUTE(SUBSTITUTE(SUBSTITUTE(SUBSTITUTE(SUBSTITUTE(SUBSTITUTE(SUBSTITUTE(SUBSTITUTE(SUBSTITUTE(SUBSTITUTE(SUBSTITUTE(SUBSTITUTE(LOWER($A14),"ё","yo"),"ю","yu"),"я","ya"),"ц","ts"),"ч","ch"),"ш","sh"),"щ","sh"),"ў","o"),"қ","q"),"ғ","g"),"ҳ","h"),"а","a"),"б","b"),"в","v"),"г","g"),"д","d"),"е","e"),"ж","j"),"з","z"),"и","i"),"й","y"),"к","k"),"л","l"),"м","m"),"н","n"),"о","o"),"п","p"),"р","r"),"с","s"),"т","t"),"у","u"),"ф","f"),"х","x"),"ъ",""),"ы","i"),"ь",""),"э","e"),"'",""),"‘",""),"’",""),"ʻ",""),"ʼ",""),"`",""))) | C14: =IF($B14="","",IFERROR(INDEX('CRM Clients'!$A$4:$A$53,MATCH($B14,'CRM Clients'!$D$4:$D$53,0)),"not found")) | D14: =IF($B14="","",IFERROR(INDEX('CRM Clients'!$B$4:$B$53,MATCH($B14,'CRM Clients'!$D$4:$D$53,0)),"")) | E14: =IF($B14="","",IF($F14=0,"no match - new client, or a typo",IF($F14>1,"CHECK PHONE - "&$F14&" clients share this name","matched"))) | F14: =IF($B14="","",COUNTIF('CRM Clients'!$D$4:$D$53,$B14))
B15: =IF($A15="","",TRIM(SUBSTITUTE(SUBSTITUTE(SUBSTITUTE(SUBSTITUTE(SUBSTITUTE(SUBSTITUTE(SUBSTITUTE(SUBSTITUTE(SUBSTITUTE(SUBSTITUTE(SUBSTITUTE(SUBSTITUTE(SUBSTITUTE(SUBSTITUTE(SUBSTITUTE(SUBSTITUTE(SUBSTITUTE(SUBSTITUTE(SUBSTITUTE(SUBSTITUTE(SUBSTITUTE(SUBSTITUTE(SUBSTITUTE(SUBSTITUTE(SUBSTITUTE(SUBSTITUTE(SUBSTITUTE(SUBSTITUTE(SUBSTITUTE(SUBSTITUTE(SUBSTITUTE(SUBSTITUTE(SUBSTITUTE(SUBSTITUTE(SUBSTITUTE(SUBSTITUTE(SUBSTITUTE(SUBSTITUTE(SUBSTITUTE(SUBSTITUTE(SUBSTITUTE(SUBSTITUTE(SUBSTITUTE(LOWER($A15),"ё","yo"),"ю","yu"),"я","ya"),"ц","ts"),"ч","ch"),"ш","sh"),"щ","sh"),"ў","o"),"қ","q"),"ғ","g"),"ҳ","h"),"а","a"),"б","b"),"в","v"),"г","g"),"д","d"),"е","e"),"ж","j"),"з","z"),"и","i"),"й","y"),"к","k"),"л","l"),"м","m"),"н","n"),"о","o"),"п","p"),"р","r"),"с","s"),"т","t"),"у","u"),"ф","f"),"х","x"),"ъ",""),"ы","i"),"ь",""),"э","e"),"'",""),"‘",""),"’",""),"ʻ",""),"ʼ",""),"`",""))) | C15: =IF($B15="","",IFERROR(INDEX('CRM Clients'!$A$4:$A$53,MATCH($B15,'CRM Clients'!$D$4:$D$53,0)),"not found")) | D15: =IF($B15="","",IFERROR(INDEX('CRM Clients'!$B$4:$B$53,MATCH($B15,'CRM Clients'!$D$4:$D$53,0)),"")) | E15: =IF($B15="","",IF($F15=0,"no match - new client, or a typo",IF($F15>1,"CHECK PHONE - "&$F15&" clients share this name","matched"))) | F15: =IF($B15="","",COUNTIF('CRM Clients'!$D$4:$D$53,$B15))
B16: =IF($A16="","",TRIM(SUBSTITUTE(SUBSTITUTE(SUBSTITUTE(SUBSTITUTE(SUBSTITUTE(SUBSTITUTE(SUBSTITUTE(SUBSTITUTE(SUBSTITUTE(SUBSTITUTE(SUBSTITUTE(SUBSTITUTE(SUBSTITUTE(SUBSTITUTE(SUBSTITUTE(SUBSTITUTE(SUBSTITUTE(SUBSTITUTE(SUBSTITUTE(SUBSTITUTE(SUBSTITUTE(SUBSTITUTE(SUBSTITUTE(SUBSTITUTE(SUBSTITUTE(SUBSTITUTE(SUBSTITUTE(SUBSTITUTE(SUBSTITUTE(SUBSTITUTE(SUBSTITUTE(SUBSTITUTE(SUBSTITUTE(SUBSTITUTE(SUBSTITUTE(SUBSTITUTE(SUBSTITUTE(SUBSTITUTE(SUBSTITUTE(SUBSTITUTE(SUBSTITUTE(SUBSTITUTE(SUBSTITUTE(LOWER($A16),"ё","yo"),"ю","yu"),"я","ya"),"ц","ts"),"ч","ch"),"ш","sh"),"щ","sh"),"ў","o"),"қ","q"),"ғ","g"),"ҳ","h"),"а","a"),"б","b"),"в","v"),"г","g"),"д","d"),"е","e"),"ж","j"),"з","z"),"и","i"),"й","y"),"к","k"),"л","l"),"м","m"),"н","n"),"о","o"),"п","p"),"р","r"),"с","s"),"т","t"),"у","u"),"ф","f"),"х","x"),"ъ",""),"ы","i"),"ь",""),"э","e"),"'",""),"‘",""),"’",""),"ʻ",""),"ʼ",""),"`",""))) | C16: =IF($B16="","",IFERROR(INDEX('CRM Clients'!$A$4:$A$53,MATCH($B16,'CRM Clients'!$D$4:$D$53,0)),"not found")) | D16: =IF($B16="","",IFERROR(INDEX('CRM Clients'!$B$4:$B$53,MATCH($B16,'CRM Clients'!$D$4:$D$53,0)),"")) | E16: =IF($B16="","",IF($F16=0,"no match - new client, or a typo",IF($F16>1,"CHECK PHONE - "&$F16&" clients share this name","matched"))) | F16: =IF($B16="","",COUNTIF('CRM Clients'!$D$4:$D$53,$B16))
B17: =IF($A17="","",TRIM(SUBSTITUTE(SUBSTITUTE(SUBSTITUTE(SUBSTITUTE(SUBSTITUTE(SUBSTITUTE(SUBSTITUTE(SUBSTITUTE(SUBSTITUTE(SUBSTITUTE(SUBSTITUTE(SUBSTITUTE(SUBSTITUTE(SUBSTITUTE(SUBSTITUTE(SUBSTITUTE(SUBSTITUTE(SUBSTITUTE(SUBSTITUTE(SUBSTITUTE(SUBSTITUTE(SUBSTITUTE(SUBSTITUTE(SUBSTITUTE(SUBSTITUTE(SUBSTITUTE(SUBSTITUTE(SUBSTITUTE(SUBSTITUTE(SUBSTITUTE(SUBSTITUTE(SUBSTITUTE(SUBSTITUTE(SUBSTITUTE(SUBSTITUTE(SUBSTITUTE(SUBSTITUTE(SUBSTITUTE(SUBSTITUTE(SUBSTITUTE(SUBSTITUTE(SUBSTITUTE(SUBSTITUTE(LOWER($A17),"ё","yo"),"ю","yu"),"я","ya"),"ц","ts"),"ч","ch"),"ш","sh"),"щ","sh"),"ў","o"),"қ","q"),"ғ","g"),"ҳ","h"),"а","a"),"б","b"),"в","v"),"г","g"),"д","d"),"е","e"),"ж","j"),"з","z"),"и","i"),"й","y"),"к","k"),"л","l"),"м","m"),"н","n"),"о","o"),"п","p"),"р","r"),"с","s"),"т","t"),"у","u"),"ф","f"),"х","x"),"ъ",""),"ы","i"),"ь",""),"э","e"),"'",""),"‘",""),"’",""),"ʻ",""),"ʼ",""),"`",""))) | C17: =IF($B17="","",IFERROR(INDEX('CRM Clients'!$A$4:$A$53,MATCH($B17,'CRM Clients'!$D$4:$D$53,0)),"not found")) | D17: =IF($B17="","",IFERROR(INDEX('CRM Clients'!$B$4:$B$53,MATCH($B17,'CRM Clients'!$D$4:$D$53,0)),"")) | E17: =IF($B17="","",IF($F17=0,"no match - new client, or a typo",IF($F17>1,"CHECK PHONE - "&$F17&" clients share this name","matched"))) | F17: =IF($B17="","",COUNTIF('CRM Clients'!$D$4:$D$53,$B17))
B18: =IF($A18="","",TRIM(SUBSTITUTE(SUBSTITUTE(SUBSTITUTE(SUBSTITUTE(SUBSTITUTE(SUBSTITUTE(SUBSTITUTE(SUBSTITUTE(SUBSTITUTE(SUBSTITUTE(SUBSTITUTE(SUBSTITUTE(SUBSTITUTE(SUBSTITUTE(SUBSTITUTE(SUBSTITUTE(SUBSTITUTE(SUBSTITUTE(SUBSTITUTE(SUBSTITUTE(SUBSTITUTE(SUBSTITUTE(SUBSTITUTE(SUBSTITUTE(SUBSTITUTE(SUBSTITUTE(SUBSTITUTE(SUBSTITUTE(SUBSTITUTE(SUBSTITUTE(SUBSTITUTE(SUBSTITUTE(SUBSTITUTE(SUBSTITUTE(SUBSTITUTE(SUBSTITUTE(SUBSTITUTE(SUBSTITUTE(SUBSTITUTE(SUBSTITUTE(SUBSTITUTE(SUBSTITUTE(SUBSTITUTE(LOWER($A18),"ё","yo"),"ю","yu"),"я","ya"),"ц","ts"),"ч","ch"),"ш","sh"),"щ","sh"),"ў","o"),"қ","q"),"ғ","g"),"ҳ","h"),"а","a"),"б","b"),"в","v"),"г","g"),"д","d"),"е","e"),"ж","j"),"з","z"),"и","i"),"й","y"),"к","k"),"л","l"),"м","m"),"н","n"),"о","o"),"п","p"),"р","r"),"с","s"),"т","t"),"у","u"),"ф","f"),"х","x"),"ъ",""),"ы","i"),"ь",""),"э","e"),"'",""),"‘",""),"’",""),"ʻ",""),"ʼ",""),"`",""))) | C18: =IF($B18="","",IFERROR(INDEX('CRM Clients'!$A$4:$A$53,MATCH($B18,'CRM Clients'!$D$4:$D$53,0)),"not found")) | D18: =IF($B18="","",IFERROR(INDEX('CRM Clients'!$B$4:$B$53,MATCH($B18,'CRM Clients'!$D$4:$D$53,0)),"")) | E18: =IF($B18="","",IF($F18=0,"no match - new client, or a typo",IF($F18>1,"CHECK PHONE - "&$F18&" clients share this name","matched"))) | F18: =IF($B18="","",COUNTIF('CRM Clients'!$D$4:$D$53,$B18))
B19: =IF($A19="","",TRIM(SUBSTITUTE(SUBSTITUTE(SUBSTITUTE(SUBSTITUTE(SUBSTITUTE(SUBSTITUTE(SUBSTITUTE(SUBSTITUTE(SUBSTITUTE(SUBSTITUTE(SUBSTITUTE(SUBSTITUTE(SUBSTITUTE(SUBSTITUTE(SUBSTITUTE(SUBSTITUTE(SUBSTITUTE(SUBSTITUTE(SUBSTITUTE(SUBSTITUTE(SUBSTITUTE(SUBSTITUTE(SUBSTITUTE(SUBSTITUTE(SUBSTITUTE(SUBSTITUTE(SUBSTITUTE(SUBSTITUTE(SUBSTITUTE(SUBSTITUTE(SUBSTITUTE(SUBSTITUTE(SUBSTITUTE(SUBSTITUTE(SUBSTITUTE(SUBSTITUTE(SUBSTITUTE(SUBSTITUTE(SUBSTITUTE(SUBSTITUTE(SUBSTITUTE(SUBSTITUTE(SUBSTITUTE(LOWER($A19),"ё","yo"),"ю","yu"),"я","ya"),"ц","ts"),"ч","ch"),"ш","sh"),"щ","sh"),"ў","o"),"қ","q"),"ғ","g"),"ҳ","h"),"а","a"),"б","b"),"в","v"),"г","g"),"д","d"),"е","e"),"ж","j"),"з","z"),"и","i"),"й","y"),"к","k"),"л","l"),"м","m"),"н","n"),"о","o"),"п","p"),"р","r"),"с","s"),"т","t"),"у","u"),"ф","f"),"х","x"),"ъ",""),"ы","i"),"ь",""),"э","e"),"'",""),"‘",""),"’",""),"ʻ",""),"ʼ",""),"`",""))) | C19: =IF($B19="","",IFERROR(INDEX('CRM Clients'!$A$4:$A$53,MATCH($B19,'CRM Clients'!$D$4:$D$53,0)),"not found")) | D19: =IF($B19="","",IFERROR(INDEX('CRM Clients'!$B$4:$B$53,MATCH($B19,'CRM Clients'!$D$4:$D$53,0)),"")) | E19: =IF($B19="","",IF($F19=0,"no match - new client, or a typo",IF($F19>1,"CHECK PHONE - "&$F19&" clients share this name","matched"))) | F19: =IF($B19="","",COUNTIF('CRM Clients'!$D$4:$D$53,$B19))
B20: =IF($A20="","",TRIM(SUBSTITUTE(SUBSTITUTE(SUBSTITUTE(SUBSTITUTE(SUBSTITUTE(SUBSTITUTE(SUBSTITUTE(SUBSTITUTE(SUBSTITUTE(SUBSTITUTE(SUBSTITUTE(SUBSTITUTE(SUBSTITUTE(SUBSTITUTE(SUBSTITUTE(SUBSTITUTE(SUBSTITUTE(SUBSTITUTE(SUBSTITUTE(SUBSTITUTE(SUBSTITUTE(SUBSTITUTE(SUBSTITUTE(SUBSTITUTE(SUBSTITUTE(SUBSTITUTE(SUBSTITUTE(SUBSTITUTE(SUBSTITUTE(SUBSTITUTE(SUBSTITUTE(SUBSTITUTE(SUBSTITUTE(SUBSTITUTE(SUBSTITUTE(SUBSTITUTE(SUBSTITUTE(SUBSTITUTE(SUBSTITUTE(SUBSTITUTE(SUBSTITUTE(SUBSTITUTE(SUBSTITUTE(LOWER($A20),"ё","yo"),"ю","yu"),"я","ya"),"ц","ts"),"ч","ch"),"ш","sh"),"щ","sh"),"ў","o"),"қ","q"),"ғ","g"),"ҳ","h"),"а","a"),"б","b"),"в","v"),"г","g"),"д","d"),"е","e"),"ж","j"),"з","z"),"и","i"),"й","y"),"к","k"),"л","l"),"м","m"),"н","n"),"о","o"),"п","p"),"р","r"),"с","s"),"т","t"),"у","u"),"ф","f"),"х","x"),"ъ",""),"ы","i"),"ь",""),"э","e"),"'",""),"‘",""),"’",""),"ʻ",""),"ʼ",""),"`",""))) | C20: =IF($B20="","",IFERROR(INDEX('CRM Clients'!$A$4:$A$53,MATCH($B20,'CRM Clients'!$D$4:$D$53,0)),"not found")) | D20: =IF($B20="","",IFERROR(INDEX('CRM Clients'!$B$4:$B$53,MATCH($B20,'CRM Clients'!$D$4:$D$53,0)),"")) | E20: =IF($B20="","",IF($F20=0,"no match - new client, or a typo",IF($F20>1,"CHECK PHONE - "&$F20&" clients share this name","matched"))) | F20: =IF($B20="","",COUNTIF('CRM Clients'!$D$4:$D$53,$B20))
B21: =IF($A21="","",TRIM(SUBSTITUTE(SUBSTITUTE(SUBSTITUTE(SUBSTITUTE(SUBSTITUTE(SUBSTITUTE(SUBSTITUTE(SUBSTITUTE(SUBSTITUTE(SUBSTITUTE(SUBSTITUTE(SUBSTITUTE(SUBSTITUTE(SUBSTITUTE(SUBSTITUTE(SUBSTITUTE(SUBSTITUTE(SUBSTITUTE(SUBSTITUTE(SUBSTITUTE(SUBSTITUTE(SUBSTITUTE(SUBSTITUTE(SUBSTITUTE(SUBSTITUTE(SUBSTITUTE(SUBSTITUTE(SUBSTITUTE(SUBSTITUTE(SUBSTITUTE(SUBSTITUTE(SUBSTITUTE(SUBSTITUTE(SUBSTITUTE(SUBSTITUTE(SUBSTITUTE(SUBSTITUTE(SUBSTITUTE(SUBSTITUTE(SUBSTITUTE(SUBSTITUTE(SUBSTITUTE(SUBSTITUTE(LOWER($A21),"ё","yo"),"ю","yu"),"я","ya"),"ц","ts"),"ч","ch"),"ш","sh"),"щ","sh"),"ў","o"),"қ","q"),"ғ","g"),"ҳ","h"),"а","a"),"б","b"),"в","v"),"г","g"),"д","d"),"е","e"),"ж","j"),"з","z"),"и","i"),"й","y"),"к","k"),"л","l"),"м","m"),"н","n"),"о","o"),"п","p"),"р","r"),"с","s"),"т","t"),"у","u"),"ф","f"),"х","x"),"ъ",""),"ы","i"),"ь",""),"э","e"),"'",""),"‘",""),"’",""),"ʻ",""),"ʼ",""),"`",""))) | C21: =IF($B21="","",IFERROR(INDEX('CRM Clients'!$A$4:$A$53,MATCH($B21,'CRM Clients'!$D$4:$D$53,0)),"not found")) | D21: =IF($B21="","",IFERROR(INDEX('CRM Clients'!$B$4:$B$53,MATCH($B21,'CRM Clients'!$D$4:$D$53,0)),"")) | E21: =IF($B21="","",IF($F21=0,"no match - new client, or a typo",IF($F21>1,"CHECK PHONE - "&$F21&" clients share this name","matched"))) | F21: =IF($B21="","",COUNTIF('CRM Clients'!$D$4:$D$53,$B21))
... B43: =IF($A43="","",TRIM(SUBSTITUTE(SUBSTITUTE(SUBSTITUTE(SUBSTITUTE(SUBSTITUTE(SUBSTITUTE(SUBSTITUTE(SUBSTITUTE(SUBSTITUTE(SUBSTITUTE(SUBSTITUTE(SUBSTITUTE(SUBSTITUTE(SUBSTITUTE(SUBSTITUTE(SUBSTITUTE(SUBSTITUTE(SUBSTITUTE(SUBSTITUTE(SUBSTITUTE(SUBSTITUTE(SUBSTITUTE(SUBSTITUTE(SUBSTITUTE(SUBSTITUTE(SUBSTITUTE(SUBSTITUTE(SUBSTITUTE(SUBSTITUTE(SUBSTITUTE(SUBSTITUTE(SUBSTITUTE(SUBSTITUTE(SUBSTITUTE(SUBSTITUTE(SUBSTITUTE(SUBSTITUTE(SUBSTITUTE(SUBSTITUTE(SUBSTITUTE(SUBSTITUTE(SUBSTITUTE(SUBSTITUTE(LOWER($A43),"ё","yo"),"ю","yu"),"я","ya"),"ц","ts"),"ч","ch"),"ш","sh"),"щ","sh"),"ў","o"),"қ","q"),"ғ","g"),"ҳ","h"),"а","a"),"б","b"),"в","v"),"г","g"),"д","d"),"е","e"),"ж","j"),"з","z"),"и","i"),"й","y"),"к","k"),"л","l"),"м","m"),"н","n"),"о","o"),"п","p"),"р","r"),"с","s"),"т","t"),"у","u"),"ф","f"),"х","x"),"ъ",""),"ы","i"),"ь",""),"э","e"),"'",""),"‘",""),"’",""),"ʻ",""),"ʼ",""),"`",""))) | C43: =IF($B43="","",IFERROR(INDEX('CRM Clients'!$A$4:$A$53,MATCH($B43,'CRM Clients'!$D$4:$D$53,0)),"not found")) | D43: =IF($B43="","",IFERROR(INDEX('CRM Clients'!$B$4:$B$53,MATCH($B43,'CRM Clients'!$D$4:$D$53,0)),"")) | E43: =IF($B43="","",IF($F43=0,"no match - new client, or a typo",IF($F43>1,"CHECK PHONE - "&$F43&" clients share this name","matched"))) | F43: =IF($B43="","",COUNTIF('CRM Clients'!$D$4:$D$53,$B43))
A46: Matching is exact after normalising, not fuzzy: it forgives alphabet and capitalisation, not misspellings. 'no match' on a name you expect usually means a real spelling difference - compare the Normalised column against the CRM Clients sheet.

Sheet Phone Cleaner
A1: Phone Cleaner
A2: Paste numbers however they are written. Out comes 998XXXXXXXXX.
A3: Number as you have it | B3: Digits only | C3: CRM format | D3: Result
A4: +998 90 123-45-67 | B4: =IF($A4="","",SUBSTITUTE(SUBSTITUTE(SUBSTITUTE(SUBSTITUTE(SUBSTITUTE(SUBSTITUTE(SUBSTITUTE(SUBSTITUTE($A4," ",""),"+",""),"-",""),"(",""),")",""),".",""),"/",""),CHAR(160),"")) | C4: =IF($B4="","",IF(AND(LEN($B4)=12,LEFT($B4,3)="998"),$B4,IF(LEN($B4)=9,"998"&$B4,IF(AND(LEN($B4)=10,LEFT($B4,1)="8"),"998"&MID($B4,2,9),IF(AND(LEN($B4)=14,LEFT($B4,5)="00998"),MID($B4,3,12),"?"))))) | D4: =IF($C4="","",IF($C4="?","cannot read - fix by hand","ok"))
A5: 998934290084 | B5: =IF($A5="","",SUBSTITUTE(SUBSTITUTE(SUBSTITUTE(SUBSTITUTE(SUBSTITUTE(SUBSTITUTE(SUBSTITUTE(SUBSTITUTE($A5," ",""),"+",""),"-",""),"(",""),")",""),".",""),"/",""),CHAR(160),"")) | C5: =IF($B5="","",IF(AND(LEN($B5)=12,LEFT($B5,3)="998"),$B5,IF(LEN($B5)=9,"998"&$B5,IF(AND(LEN($B5)=10,LEFT($B5,1)="8"),"998"&MID($B5,2,9),IF(AND(LEN($B5)=14,LEFT($B5,5)="00998"),MID($B5,3,12),"?"))))) | D5: =IF($C5="","",IF($C5="?","cannot read - fix by hand","ok"))
A6: 90 123 45 67 | B6: =IF($A6="","",SUBSTITUTE(SUBSTITUTE(SUBSTITUTE(SUBSTITUTE(SUBSTITUTE(SUBSTITUTE(SUBSTITUTE(SUBSTITUTE($A6," ",""),"+",""),"-",""),"(",""),")",""),".",""),"/",""),CHAR(160),"")) | C6: =IF($B6="","",IF(AND(LEN($B6)=12,LEFT($B6,3)="998"),$B6,IF(LEN($B6)=9,"998"&$B6,IF(AND(LEN($B6)=10,LEFT($B6,1)="8"),"998"&MID($B6,2,9),IF(AND(LEN($B6)=14,LEFT($B6,5)="00998"),MID($B6,3,12),"?"))))) | D6: =IF($C6="","",IF($C6="?","cannot read - fix by hand","ok"))
A7: (99) 807-27-27 | B7: =IF($A7="","",SUBSTITUTE(SUBSTITUTE(SUBSTITUTE(SUBSTITUTE(SUBSTITUTE(SUBSTITUTE(SUBSTITUTE(SUBSTITUTE($A7," ",""),"+",""),"-",""),"(",""),")",""),".",""),"/",""),CHAR(160),"")) | C7: =IF($B7="","",IF(AND(LEN($B7)=12,LEFT($B7,3)="998"),$B7,IF(LEN($B7)=9,"998"&$B7,IF(AND(LEN($B7)=10,LEFT($B7,1)="8"),"998"&MID($B7,2,9),IF(AND(LEN($B7)=14,LEFT($B7,5)="00998"),MID($B7,3,12),"?"))))) | D7: =IF($C7="","",IF($C7="?","cannot read - fix by hand","ok"))
A8: 8 94 5053000 | B8: =IF($A8="","",SUBSTITUTE(SUBSTITUTE(SUBSTITUTE(SUBSTITUTE(SUBSTITUTE(SUBSTITUTE(SUBSTITUTE(SUBSTITUTE($A8," ",""),"+",""),"-",""),"(",""),")",""),".",""),"/",""),CHAR(160),"")) | C8: =IF($B8="","",IF(AND(LEN($B8)=12,LEFT($B8,3)="998"),$B8,IF(LEN($B8)=9,"998"&$B8,IF(AND(LEN($B8)=10,LEFT($B8,1)="8"),"998"&MID($B8,2,9),IF(AND(LEN($B8)=14,LEFT($B8,5)="00998"),MID($B8,3,12),"?"))))) | D8: =IF($C8="","",IF($C8="?","cannot read - fix by hand","ok"))
A9: 00998913421133 | B9: =IF($A9="","",SUBSTITUTE(SUBSTITUTE(SUBSTITUTE(SUBSTITUTE(SUBSTITUTE(SUBSTITUTE(SUBSTITUTE(SUBSTITUTE($A9," ",""),"+",""),"-",""),"(",""),")",""),".",""),"/",""),CHAR(160),"")) | C9: =IF($B9="","",IF(AND(LEN($B9)=12,LEFT($B9,3)="998"),$B9,IF(LEN($B9)=9,"998"&$B9,IF(AND(LEN($B9)=10,LEFT($B9,1)="8"),"998"&MID($B9,2,9),IF(AND(LEN($B9)=14,LEFT($B9,5)="00998"),MID($B9,3,12),"?"))))) | D9: =IF($C9="","",IF($C9="?","cannot read - fix by hand","ok"))
A10: 998-97-974-04-24 | B10: =IF($A10="","",SUBSTITUTE(SUBSTITUTE(SUBSTITUTE(SUBSTITUTE(SUBSTITUTE(SUBSTITUTE(SUBSTITUTE(SUBSTITUTE($A10," ",""),"+",""),"-",""),"(",""),")",""),".",""),"/",""),CHAR(160),"")) | C10: =IF($B10="","",IF(AND(LEN($B10)=12,LEFT($B10,3)="998"),$B10,IF(LEN($B10)=9,"998"&$B10,IF(AND(LEN($B10)=10,LEFT($B10,1)="8"),"998"&MID($B10,2,9),IF(AND(LEN($B10)=14,LEFT($B10,5)="00998"),MID($B10,3,12),"?"))))) | D10: =IF($C10="","",IF($C10="?","cannot read - fix by hand","ok"))
A11: 93 966 88 85 | B11: =IF($A11="","",SUBSTITUTE(SUBSTITUTE(SUBSTITUTE(SUBSTITUTE(SUBSTITUTE(SUBSTITUTE(SUBSTITUTE(SUBSTITUTE($A11," ",""),"+",""),"-",""),"(",""),")",""),".",""),"/",""),CHAR(160),"")) | C11: =IF($B11="","",IF(AND(LEN($B11)=12,LEFT($B11,3)="998"),$B11,IF(LEN($B11)=9,"998"&$B11,IF(AND(LEN($B11)=10,LEFT($B11,1)="8"),"998"&MID($B11,2,9),IF(AND(LEN($B11)=14,LEFT($B11,5)="00998"),MID($B11,3,12),"?"))))) | D11: =IF($C11="","",IF($C11="?","cannot read - fix by hand","ok"))
A12: не указан | B12: =IF($A12="","",SUBSTITUTE(SUBSTITUTE(SUBSTITUTE(SUBSTITUTE(SUBSTITUTE(SUBSTITUTE(SUBSTITUTE(SUBSTITUTE($A12," ",""),"+",""),"-",""),"(",""),")",""),".",""),"/",""),CHAR(160),"")) | C12: =IF($B12="","",IF(AND(LEN($B12)=12,LEFT($B12,3)="998"),$B12,IF(LEN($B12)=9,"998"&$B12,IF(AND(LEN($B12)=10,LEFT($B12,1)="8"),"998"&MID($B12,2,9),IF(AND(LEN($B12)=14,LEFT($B12,5)="00998"),MID($B12,3,12),"?"))))) | D12: =IF($C12="","",IF($C12="?","cannot read - fix by hand","ok"))
B13: =IF($A13="","",SUBSTITUTE(SUBSTITUTE(SUBSTITUTE(SUBSTITUTE(SUBSTITUTE(SUBSTITUTE(SUBSTITUTE(SUBSTITUTE($A13," ",""),"+",""),"-",""),"(",""),")",""),".",""),"/",""),CHAR(160),"")) | C13: =IF($B13="","",IF(AND(LEN($B13)=12,LEFT($B13,3)="998"),$B13,IF(LEN($B13)=9,"998"&$B13,IF(AND(LEN($B13)=10,LEFT($B13,1)="8"),"998"&MID($B13,2,9),IF(AND(LEN($B13)=14,LEFT($B13,5)="00998"),MID($B13,3,12),"?"))))) | D13: =IF($C13="","",IF($C13="?","cannot read - fix by hand","ok"))
B14: =IF($A14="","",SUBSTITUTE(SUBSTITUTE(SUBSTITUTE(SUBSTITUTE(SUBSTITUTE(SUBSTITUTE(SUBSTITUTE(SUBSTITUTE($A14," ",""),"+",""),"-",""),"(",""),")",""),".",""),"/",""),CHAR(160),"")) | C14: =IF($B14="","",IF(AND(LEN($B14)=12,LEFT($B14,3)="998"),$B14,IF(LEN($B14)=9,"998"&$B14,IF(AND(LEN($B14)=10,LEFT($B14,1)="8"),"998"&MID($B14,2,9),IF(AND(LEN($B14)=14,LEFT($B14,5)="00998"),MID($B14,3,12),"?"))))) | D14: =IF($C14="","",IF($C14="?","cannot read - fix by hand","ok"))
B15: =IF($A15="","",SUBSTITUTE(SUBSTITUTE(SUBSTITUTE(SUBSTITUTE(SUBSTITUTE(SUBSTITUTE(SUBSTITUTE(SUBSTITUTE($A15," ",""),"+",""),"-",""),"(",""),")",""),".",""),"/",""),CHAR(160),"")) | C15: =IF($B15="","",IF(AND(LEN($B15)=12,LEFT($B15,3)="998"),$B15,IF(LEN($B15)=9,"998"&$B15,IF(AND(LEN($B15)=10,LEFT($B15,1)="8"),"998"&MID($B15,2,9),IF(AND(LEN($B15)=14,LEFT($B15,5)="00998"),MID($B15,3,12),"?"))))) | D15: =IF($C15="","",IF($C15="?","cannot read - fix by hand","ok"))
B16: =IF($A16="","",SUBSTITUTE(SUBSTITUTE(SUBSTITUTE(SUBSTITUTE(SUBSTITUTE(SUBSTITUTE(SUBSTITUTE(SUBSTITUTE($A16," ",""),"+",""),"-",""),"(",""),")",""),".",""),"/",""),CHAR(160),"")) | C16: =IF($B16="","",IF(AND(LEN($B16)=12,LEFT($B16,3)="998"),$B16,IF(LEN($B16)=9,"998"&$B16,IF(AND(LEN($B16)=10,LEFT($B16,1)="8"),"998"&MID($B16,2,9),IF(AND(LEN($B16)=14,LEFT($B16,5)="00998"),MID($B16,3,12),"?"))))) | D16: =IF($C16="","",IF($C16="?","cannot read - fix by hand","ok"))
B17: =IF($A17="","",SUBSTITUTE(SUBSTITUTE(SUBSTITUTE(SUBSTITUTE(SUBSTITUTE(SUBSTITUTE(SUBSTITUTE(SUBSTITUTE($A17," ",""),"+",""),"-",""),"(",""),")",""),".",""),"/",""),CHAR(160),"")) | C17: =IF($B17="","",IF(AND(LEN($B17)=12,LEFT($B17,3)="998"),$B17,IF(LEN($B17)=9,"998"&$B17,IF(AND(LEN($B17)=10,LEFT($B17,1)="8"),"998"&MID($B17,2,9),IF(AND(LEN($B17)=14,LEFT($B17,5)="00998"),MID($B17,3,12),"?"))))) | D17: =IF($C17="","",IF($C17="?","cannot read - fix by hand","ok"))
B18: =IF($A18="","",SUBSTITUTE(SUBSTITUTE(SUBSTITUTE(SUBSTITUTE(SUBSTITUTE(SUBSTITUTE(SUBSTITUTE(SUBSTITUTE($A18," ",""),"+",""),"-",""),"(",""),")",""),".",""),"/",""),CHAR(160),"")) | C18: =IF($B18="","",IF(AND(LEN($B18)=12,LEFT($B18,3)="998"),$B18,IF(LEN($B18)=9,"998"&$B18,IF(AND(LEN($B18)=10,LEFT($B18,1)="8"),"998"&MID($B18,2,9),IF(AND(LEN($B18)=14,LEFT($B18,5)="00998"),MID($B18,3,12),"?"))))) | D18: =IF($C18="","",IF($C18="?","cannot read - fix by hand","ok"))
B19: =IF($A19="","",SUBSTITUTE(SUBSTITUTE(SUBSTITUTE(SUBSTITUTE(SUBSTITUTE(SUBSTITUTE(SUBSTITUTE(SUBSTITUTE($A19," ",""),"+",""),"-",""),"(",""),")",""),".",""),"/",""),CHAR(160),"")) | C19: =IF($B19="","",IF(AND(LEN($B19)=12,LEFT($B19,3)="998"),$B19,IF(LEN($B19)=9,"998"&$B19,IF(AND(LEN($B19)=10,LEFT($B19,1)="8"),"998"&MID($B19,2,9),IF(AND(LEN($B19)=14,LEFT($B19,5)="00998"),MID($B19,3,12),"?"))))) | D19: =IF($C19="","",IF($C19="?","cannot read - fix by hand","ok"))
B20: =IF($A20="","",SUBSTITUTE(SUBSTITUTE(SUBSTITUTE(SUBSTITUTE(SUBSTITUTE(SUBSTITUTE(SUBSTITUTE(SUBSTITUTE($A20," ",""),"+",""),"-",""),"(",""),")",""),".",""),"/",""),CHAR(160),"")) | C20: =IF($B20="","",IF(AND(LEN($B20)=12,LEFT($B20,3)="998"),$B20,IF(LEN($B20)=9,"998"&$B20,IF(AND(LEN($B20)=10,LEFT($B20,1)="8"),"998"&MID($B20,2,9),IF(AND(LEN($B20)=14,LEFT($B20,5)="00998"),MID($B20,3,12),"?"))))) | D20: =IF($C20="","",IF($C20="?","cannot read - fix by hand","ok"))
B21: =IF($A21="","",SUBSTITUTE(SUBSTITUTE(SUBSTITUTE(SUBSTITUTE(SUBSTITUTE(SUBSTITUTE(SUBSTITUTE(SUBSTITUTE($A21," ",""),"+",""),"-",""),"(",""),")",""),".",""),"/",""),CHAR(160),"")) | C21: =IF($B21="","",IF(AND(LEN($B21)=12,LEFT($B21,3)="998"),$B21,IF(LEN($B21)=9,"998"&$B21,IF(AND(LEN($B21)=10,LEFT($B21,1)="8"),"998"&MID($B21,2,9),IF(AND(LEN($B21)=14,LEFT($B21,5)="00998"),MID($B21,3,12),"?"))))) | D21: =IF($C21="","",IF($C21="?","cannot read - fix by hand","ok"))
B22: =IF($A22="","",SUBSTITUTE(SUBSTITUTE(SUBSTITUTE(SUBSTITUTE(SUBSTITUTE(SUBSTITUTE(SUBSTITUTE(SUBSTITUTE($A22," ",""),"+",""),"-",""),"(",""),")",""),".",""),"/",""),CHAR(160),"")) | C22: =IF($B22="","",IF(AND(LEN($B22)=12,LEFT($B22,3)="998"),$B22,IF(LEN($B22)=9,"998"&$B22,IF(AND(LEN($B22)=10,LEFT($B22,1)="8"),"998"&MID($B22,2,9),IF(AND(LEN($B22)=14,LEFT($B22,5)="00998"),MID($B22,3,12),"?"))))) | D22: =IF($C22="","",IF($C22="?","cannot read - fix by hand","ok"))
B23: =IF($A23="","",SUBSTITUTE(SUBSTITUTE(SUBSTITUTE(SUBSTITUTE(SUBSTITUTE(SUBSTITUTE(SUBSTITUTE(SUBSTITUTE($A23," ",""),"+",""),"-",""),"(",""),")",""),".",""),"/",""),CHAR(160),"")) | C23: =IF($B23="","",IF(AND(LEN($B23)=12,LEFT($B23,3)="998"),$B23,IF(LEN($B23)=9,"998"&$B23,IF(AND(LEN($B23)=10,LEFT($B23,1)="8"),"998"&MID($B23,2,9),IF(AND(LEN($B23)=14,LEFT($B23,5)="00998"),MID($B23,3,12),"?"))))) | D23: =IF($C23="","",IF($C23="?","cannot read - fix by hand","ok"))
B24: =IF($A24="","",SUBSTITUTE(SUBSTITUTE(SUBSTITUTE(SUBSTITUTE(SUBSTITUTE(SUBSTITUTE(SUBSTITUTE(SUBSTITUTE($A24," ",""),"+",""),"-",""),"(",""),")",""),".",""),"/",""),CHAR(160),"")) | C24: =IF($B24="","",IF(AND(LEN($B24)=12,LEFT($B24,3)="998"),$B24,IF(LEN($B24)=9,"998"&$B24,IF(AND(LEN($B24)=10,LEFT($B24,1)="8"),"998"&MID($B24,2,9),IF(AND(LEN($B24)=14,LEFT($B24,5)="00998"),MID($B24,3,12),"?"))))) | D24: =IF($C24="","",IF($C24="?","cannot read - fix by hand","ok"))
... B33: =IF($A33="","",SUBSTITUTE(SUBSTITUTE(SUBSTITUTE(SUBSTITUTE(SUBSTITUTE(SUBSTITUTE(SUBSTITUTE(SUBSTITUTE($A33," ",""),"+",""),"-",""),"(",""),")",""),".",""),"/",""),CHAR(160),"")) | C33: =IF($B33="","",IF(AND(LEN($B33)=12,LEFT($B33,3)="998"),$B33,IF(LEN($B33)=9,"998"&$B33,IF(AND(LEN($B33)=10,LEFT($B33,1)="8"),"998"&MID($B33,2,9),IF(AND(LEN($B33)=14,LEFT($B33,5)="00998"),MID($B33,3,12),"?"))))) | D33: =IF($C33="","",IF($C33="?","cannot read - fix by hand","ok"))

Sheet Receivables
A1: Receivables
A2: Who owes what, and for how long. Ages against today's date every time the file opens.
A3: Order | B3: Client | C3: Phone | D3: Due date | E3: Order total | F3: Paid | G3: Outstanding | H3: Days overdue | I3: Bucket
A4: 2026-06-0035 | B4: SH N | C4: 998942779491 | D4: 46192 | E4: 2842000 | F4: 0 | G4: =$E4-$F4 | H4: =IF($G4<=0,"",TODAY()-$D4) | I4: =IF($G4<=0,"paid",IF(TODAY()-$D4<=0,"not due",IF(TODAY()-$D4<=30,"0-30",IF(TODAY()-$D4<=60,"31-60",IF(TODAY()-$D4<=90,"61-90","90+")))))
A5: 2026-09-0072 | B5: Нематжон | C5: 998907946622 | D5: 46283 | E5: 13500000 | F5: 11800000 | G5: =$E5-$F5 | H5: =IF($G5<=0,"",TODAY()-$D5) | I5: =IF($G5<=0,"paid",IF(TODAY()-$D5<=0,"not due",IF(TODAY()-$D5<=30,"0-30",IF(TODAY()-$D5<=60,"31-60",IF(TODAY()-$D5<=90,"61-90","90+")))))
A6: 2026-09-0073 | B6: Ortik | C6: 998935800787 | D6: 46282 | E6: 5300000 | F6: 5100000 | G6: =$E6-$F6 | H6: =IF($G6<=0,"",TODAY()-$D6) | I6: =IF($G6<=0,"paid",IF(TODAY()-$D6<=0,"not due",IF(TODAY()-$D6<=30,"0-30",IF(TODAY()-$D6<=60,"31-60",IF(TODAY()-$D6<=90,"61-90","90+")))))
A7: 2026-09-0074 | B7: Озодбек | C7: 998952196655 | D7: 46285 | E7: 4808400 | F7: 0 | G7: =$E7-$F7 | H7: =IF($G7<=0,"",TODAY()-$D7) | I7: =IF($G7<=0,"paid",IF(TODAY()-$D7<=0,"not due",IF(TODAY()-$D7<=30,"0-30",IF(TODAY()-$D7<=60,"31-60",IF(TODAY()-$D7<=90,"61-90","90+")))))
A8: 2026-09-0075 | B8: Адхам ака | C8: 998881480576 | D8: 46285 | E8: 5074020 | F8: 0 | G8: =$E8-$F8 | H8: =IF($G8<=0,"",TODAY()-$D8) | I8: =IF($G8<=0,"paid",IF(TODAY()-$D8<=0,"not due",IF(TODAY()-$D8<=30,"0-30",IF(TODAY()-$D8<=60,"31-60",IF(TODAY()-$D8<=90,"61-90","90+")))))
A9: 2026-09-0076 | B9: Ziyo Ziyayev | C9: 998909045653 | D9: 46288 | E9: 9262000 | F9: 1000000 | G9: =$E9-$F9 | H9: =IF($G9<=0,"",TODAY()-$D9) | I9: =IF($G9<=0,"paid",IF(TODAY()-$D9<=0,"not due",IF(TODAY()-$D9<=30,"0-30",IF(TODAY()-$D9<=60,"31-60",IF(TODAY()-$D9<=90,"61-90","90+")))))
A10: 2026-09-0077 | B10: Baxodir | C10: 998934290084 | D10: 46283 | E10: 3005040 | F10: 0 | G10: =$E10-$F10 | H10: =IF($G10<=0,"",TODAY()-$D10) | I10: =IF($G10<=0,"paid",IF(TODAY()-$D10<=0,"not due",IF(TODAY()-$D10<=30,"0-30",IF(TODAY()-$D10<=60,"31-60",IF(TODAY()-$D10<=90,"61-90","90+")))))
A11: 2026-08-0081 | B11: Журавой | C11: 998000000000 | D11: 46283 | E11: 22500000 | F11: 0 | G11: =$E11-$F11 | H11: =IF($G11<=0,"",TODAY()-$D11) | I11: =IF($G11<=0,"paid",IF(TODAY()-$D11<=0,"not due",IF(TODAY()-$D11<=30,"0-30",IF(TODAY()-$D11<=60,"31-60",IF(TODAY()-$D11<=90,"61-90","90+")))))
F12: Total | G12: =SUM($G$4:$G$11)
A15: Aging summary
A16: Bucket | B16: Orders | C16: Outstanding
A17: not due | B17: =COUNTIFS($I$4:$I$11,$A17) | C17: =SUMIFS($G$4:$G$11,$I$4:$I$11,$A17)
A18: 0-30 | B18: =COUNTIFS($I$4:$I$11,$A18) | C18: =SUMIFS($G$4:$G$11,$I$4:$I$11,$A18)
A19: 31-60 | B19: =COUNTIFS($I$4:$I$11,$A19) | C19: =SUMIFS($G$4:$G$11,$I$4:$I$11,$A19)
A20: 61-90 | B20: =COUNTIFS($I$4:$I$11,$A20) | C20: =SUMIFS($G$4:$G$11,$I$4:$I$11,$A20)
A21: 90+ | B21: =COUNTIFS($I$4:$I$11,$A21) | C21: =SUMIFS($G$4:$G$11,$I$4:$I$11,$A21)
A22: Total | B22: =SUM($B$17:$B$21) | C22: =SUM($C$17:$C$21)

Sheet Money in Words
A1: Money in Words
A2: For invoices and contracts. Type an amount in the yellow column.
A3: Amount (UZS) | B3: In words | D3: working - the four digit groups, then their words | M3: lookup tables - leave alone
A4: 13500000 | B4: =IF($A4="","",IF(INT($A4)=0,"nol so'm",TRIM(IF($D4>0,$H4&" milliard ","")&IF($E4>0,$I4&" million ","")&IF($F4>0,$J4&" ming ","")&$K4)&" so'm")) | D4: =IF($A4="","",INT(INT($A4)/1000000000)) | E4: =IF($A4="","",INT(MOD(INT($A4),1000000000)/1000000)) | F4: =IF($A4="","",INT(MOD(INT($A4),1000000)/1000)) | G4: =IF($A4="","",MOD(INT($A4),1000)) | H4: =IF($A4="","",IF($D4=0,"",TRIM(IF(INT($D4/100)>0,INDEX($N$4:$N$13,INT($D4/100)+1)&" yuz ","")&IF(MOD($D4,100)>=20,INDEX($O$4:$O$13,INT(MOD($D4,100)/10)+1)&" "&INDEX($N$4:$N$13,MOD(MOD($D4,100),10)+1),IF(MOD($D4,100)>=10,"o'n "&INDEX($N$4:$N$13,MOD($D4,100)-10+1),INDEX($N$4:$N$13,MOD($D4,100)+1)))))) | I4: =IF($A4="","",IF($E4=0,"",TRIM(IF(INT($E4/100)>0,INDEX($N$4:$N$13,INT($E4/100)+1)&" yuz ","")&IF(MOD($E4,100)>=20,INDEX($O$4:$O$13,INT(MOD($E4,100)/10)+1)&" "&INDEX($N$4:$N$13,MOD(MOD($E4,100),10)+1),IF(MOD($E4,100)>=10,"o'n "&INDEX($N$4:$N$13,MOD($E4,100)-10+1),INDEX($N$4:$N$13,MOD($E4,100)+1)))))) | J4: =IF($A4="","",IF($F4=0,"",TRIM(IF(INT($F4/100)>0,INDEX($N$4:$N$13,INT($F4/100)+1)&" yuz ","")&IF(MOD($F4,100)>=20,INDEX($O$4:$O$13,INT(MOD($F4,100)/10)+1)&" "&INDEX($N$4:$N$13,MOD(MOD($F4,100),10)+1),IF(MOD($F4,100)>=10,"o'n "&INDEX($N$4:$N$13,MOD($F4,100)-10+1),INDEX($N$4:$N$13,MOD($F4,100)+1)))))) | K4: =IF($A4="","",IF($G4=0,"",TRIM(IF(INT($G4/100)>0,INDEX($N$4:$N$13,INT($G4/100)+1)&" yuz ","")&IF(MOD($G4,100)>=20,INDEX($O$4:$O$13,INT(MOD($G4,100)/10)+1)&" "&INDEX($N$4:$N$13,MOD(MOD($G4,100),10)+1),IF(MOD($G4,100)>=10,"o'n "&INDEX($N$4:$N$13,MOD($G4,100)-10+1),INDEX($N$4:$N$13,MOD($G4,100)+1)))))) | M4: 0
A5: 3005040 | B5: =IF($A5="","",IF(INT($A5)=0,"nol so'm",TRIM(IF($D5>0,$H5&" milliard ","")&IF($E5>0,$I5&" million ","")&IF($F5>0,$J5&" ming ","")&$K5)&" so'm")) | D5: =IF($A5="","",INT(INT($A5)/1000000000)) | E5: =IF($A5="","",INT(MOD(INT($A5),1000000000)/1000000)) | F5: =IF($A5="","",INT(MOD(INT($A5),1000000)/1000)) | G5: =IF($A5="","",MOD(INT($A5),1000)) | H5: =IF($A5="","",IF($D5=0,"",TRIM(IF(INT($D5/100)>0,INDEX($N$4:$N$13,INT($D5/100)+1)&" yuz ","")&IF(MOD($D5,100)>=20,INDEX($O$4:$O$13,INT(MOD($D5,100)/10)+1)&" "&INDEX($N$4:$N$13,MOD(MOD($D5,100),10)+1),IF(MOD($D5,100)>=10,"o'n "&INDEX($N$4:$N$13,MOD($D5,100)-10+1),INDEX($N$4:$N$13,MOD($D5,100)+1)))))) | I5: =IF($A5="","",IF($E5=0,"",TRIM(IF(INT($E5/100)>0,INDEX($N$4:$N$13,INT($E5/100)+1)&" yuz ","")&IF(MOD($E5,100)>=20,INDEX($O$4:$O$13,INT(MOD($E5,100)/10)+1)&" "&INDEX($N$4:$N$13,MOD(MOD($E5,100),10)+1),IF(MOD($E5,100)>=10,"o'n "&INDEX($N$4:$N$13,MOD($E5,100)-10+1),INDEX($N$4:$N$13,MOD($E5,100)+1)))))) | J5: =IF($A5="","",IF($F5=0,"",TRIM(IF(INT($F5/100)>0,INDEX($N$4:$N$13,INT($F5/100)+1)&" yuz ","")&IF(MOD($F5,100)>=20,INDEX($O$4:$O$13,INT(MOD($F5,100)/10)+1)&" "&INDEX($N$4:$N$13,MOD(MOD($F5,100),10)+1),IF(MOD($F5,100)>=10,"o'n "&INDEX($N$4:$N$13,MOD($F5,100)-10+1),INDEX($N$4:$N$13,MOD($F5,100)+1)))))) | K5: =IF($A5="","",IF($G5=0,"",TRIM(IF(INT($G5/100)>0,INDEX($N$4:$N$13,INT($G5/100)+1)&" yuz ","")&IF(MOD($G5,100)>=20,INDEX($O$4:$O$13,INT(MOD($G5,100)/10)+1)&" "&INDEX($N$4:$N$13,MOD(MOD($G5,100),10)+1),IF(MOD($G5,100)>=10,"o'n "&INDEX($N$4:$N$13,MOD($G5,100)-10+1),INDEX($N$4:$N$13,MOD($G5,100)+1)))))) | M5: 1 | N5: bir
A6: 22500000 | B6: =IF($A6="","",IF(INT($A6)=0,"nol so'm",TRIM(IF($D6>0,$H6&" milliard ","")&IF($E6>0,$I6&" million ","")&IF($F6>0,$J6&" ming ","")&$K6)&" so'm")) | D6: =IF($A6="","",INT(INT($A6)/1000000000)) | E6: =IF($A6="","",INT(MOD(INT($A6),1000000000)/1000000)) | F6: =IF($A6="","",INT(MOD(INT($A6),1000000)/1000)) | G6: =IF($A6="","",MOD(INT($A6),1000)) | H6: =IF($A6="","",IF($D6=0,"",TRIM(IF(INT($D6/100)>0,INDEX($N$4:$N$13,INT($D6/100)+1)&" yuz ","")&IF(MOD($D6,100)>=20,INDEX($O$4:$O$13,INT(MOD($D6,100)/10)+1)&" "&INDEX($N$4:$N$13,MOD(MOD($D6,100),10)+1),IF(MOD($D6,100)>=10,"o'n "&INDEX($N$4:$N$13,MOD($D6,100)-10+1),INDEX($N$4:$N$13,MOD($D6,100)+1)))))) | I6: =IF($A6="","",IF($E6=0,"",TRIM(IF(INT($E6/100)>0,INDEX($N$4:$N$13,INT($E6/100)+1)&" yuz ","")&IF(MOD($E6,100)>=20,INDEX($O$4:$O$13,INT(MOD($E6,100)/10)+1)&" "&INDEX($N$4:$N$13,MOD(MOD($E6,100),10)+1),IF(MOD($E6,100)>=10,"o'n "&INDEX($N$4:$N$13,MOD($E6,100)-10+1),INDEX($N$4:$N$13,MOD($E6,100)+1)))))) | J6: =IF($A6="","",IF($F6=0,"",TRIM(IF(INT($F6/100)>0,INDEX($N$4:$N$13,INT($F6/100)+1)&" yuz ","")&IF(MOD($F6,100)>=20,INDEX($O$4:$O$13,INT(MOD($F6,100)/10)+1)&" "&INDEX($N$4:$N$13,MOD(MOD($F6,100),10)+1),IF(MOD($F6,100)>=10,"o'n "&INDEX($N$4:$N$13,MOD($F6,100)-10+1),INDEX($N$4:$N$13,MOD($F6,100)+1)))))) | K6: =IF($A6="","",IF($G6=0,"",TRIM(IF(INT($G6/100)>0,INDEX($N$4:$N$13,INT($G6/100)+1)&" yuz ","")&IF(MOD($G6,100)>=20,INDEX($O$4:$O$13,INT(MOD($G6,100)/10)+1)&" "&INDEX($N$4:$N$13,MOD(MOD($G6,100),10)+1),IF(MOD($G6,100)>=10,"o'n "&INDEX($N$4:$N$13,MOD($G6,100)-10+1),INDEX($N$4:$N$13,MOD($G6,100)+1)))))) | M6: 2 | N6: ikki | O6: yigirma
