Workbook
Name BreakAllow: Settings!$C$6
Name DebtCap: Settings!$C$7
Name EntryTypes: Settings!$F$6:$F$8
Name RateDates: Settings!$B$13:$B$32
Name RateValues: Settings!$C$13:$C$32
Name RejectAlarm: Settings!$C$8
Name StatusList: Settings!$G$6:$G$7
Name WeekStarts: Weeks!$A$7:$A$59
Name WorkerIDs: Workers!$A$6:$A$17
Name WorkerNames: Workers!$B$6:$B$17
Name YesNo: Settings!$H$6:$H$7

Sheet Home
A1: ◆ Donabay | C1: Home | E1: Daily Log | G1: Cash Ledger | J1: Weekly Pay | M1: Payslip | O1: Workers | Q1: Settings | S1: Guide | U1: · | V1: History | X1: Weeks | Z1: Checks
T2: row
B3: Dashboard | Q3: Week of | R3: =TODAY()-WEEKDAY(TODAY(),2)+1 -> 46286 | T3: =IFERROR(MATCH($R$3,Weeks!$A$7:$A$59,0),0) -> 1
B4: ="This week · "&TEXT($R$3,"d mmm")&" – "&TEXT($R$3+6,"d mmm yyyy")&" · updates automatically every Monday" -> This week · 21 Sep – 27 Sep 2026 · updates automatically every Monday
B6: GOOD BLOCKS | E6: CREW EARNED (SO'M) | H6: CREW-DAYS | K6: REJECT RATE | N6: ADVANCES THIS WEEK | Q6: OWED TO CREW NOW
B7: {=IF($T$3=0,0,INDEX(Weeks!$E$7:$E$59,$T$3))} -> 11857 | E7: {=IF($T$3=0,0,INDEX(Weeks!$G$7:$G$59,$T$3))} -> 5928500 | H7: {=IF($T$3=0,0,INDEX(Weeks!$H$7:$H$59,$T$3))} -> 24 | K7: {=IF($T$3=0,"",INDEX(Weeks!$I$7:$I$59,$T$3))} -> 0.010101853 | N7: =SUMIFS('Cash Ledger'!$E$7:$E$1006,'Cash Ledger'!$D$7:$D$1006,"Advance",'Cash Ledger'!$B$7:$B$1006,">="&$R$3,'Cash Ledger'!$B$7:$B$1006,"<="&($R$3+6)) -> 650000 | Q7: =SUMIF($O$30:$O$41,">0") -> 5278500
B8: {="of "&TEXT(IF($T$3=0,0,INDEX(Weeks!$C$7:$C$59,$T$3)),"#,##0")&" moulded"} -> of 11,978 moulded | E8: ="the week's pot, shared by days" -> the week's pot, shared by days | H8: =IF(N(H7)=0,"no days logged yet",TEXT(B7/H7,"#,##0")&" good blocks per crew-day") -> 494 good blocks per crew-day | K8: =IF(N(K7)=0,"no production yet",IF(K7>RejectAlarm,"⚠ above the "&TEXT(RejectAlarm,"0%")&" alarm","normal · alarm at "&TEXT(RejectAlarm,"0%"))) -> normal · alarm at 8% | N8: =COUNTIFS('Cash Ledger'!$D$7:$D$1006,"Advance",'Cash Ledger'!$B$7:$B$1006,">="&$R$3,'Cash Ledger'!$B$7:$B$1006,"<="&($R$3+6))&" advance(s) given" -> 2 advance(s) given | Q8: ="earned so far minus cash given" -> earned so far minus cash given
B11: Workbook health | K11: Quick actions
B12: =Checks!C5 -> ALL CHECKS OK | K12: › Log today's production | O12: Blocks moulded, broken, who came
B13: =Checks!B8 -> Worker list is clean (names unique, status set) | I13: =IF(Checks!C8="OK","✓ OK",Checks!C8) -> ✓ OK | K13: › Record an advance | O13: Date, worker, 'Advance', amount
B14: =Checks!B9 -> Daily Log rows without problems | I14: =IF(Checks!C9="OK","✓ OK",Checks!C9) -> ✓ OK | K14: › Run payday | O14: Pay the TO PAY column, copy the list
B15: =Checks!B10 -> Cash Ledger entries are complete and valid | I15: =IF(Checks!C10="OK","✓ OK",Checks!C10) -> ✓ OK | K15: › Print a payslip | O15: Pick week + worker, print, sign
B16: =Checks!B11 -> Every week's pot is shared out | I16: =IF(Checks!C11="OK","✓ OK",Checks!C11) -> ✓ OK | K16: › See one worker's history | O16: Week-by-week earnings and cash
B17: =Checks!B12 -> Worker shares add up to each week's pot | I17: =IF(Checks!C12="OK","✓ OK",Checks!C12) -> ✓ OK | K17: › Add or remove a worker | O17: Fill a slot, or set status to Left
B18: =Checks!B13 -> A pay rate is set | I18: =IF(Checks!C13="OK","✓ OK",Checks!C13) -> ✓ OK | K18: › Change the pay rate | O18: Add a new row with a start date
B19: =Checks!B14 -> Rate dates are in order, oldest first | I19: =IF(Checks!C14="OK","✓ OK",Checks!C14) -> ✓ OK | K19: › How this works | O19: Step-by-step instructions
B20: =Checks!B15 -> Cash Ledger has room left | I20: =IF(Checks!C15="OK","✓ OK",Checks!C15) -> ✓ OK
B21: =Checks!B16 -> Worker slots left | I21: =IF(Checks!C16="OK","✓ OK",Checks!C16) -> ✓ OK
B22: =Checks!B19 -> Advances bigger than what the worker had earned so far | I22: =Checks!C19 -> 0
B23: =Checks!B20 -> Weeks with a high reject rate | I23: =Checks!C20 -> 0
B27: Crew this week
B28: ="Owed now = everything earned up to this week, minus all cash given. Positive = you owe the worker." -> Owed now = everything earned up to this week, minus all cash given. Positive = you owe the worker.
B29: WORKER | F29: DAYS | I29: EARNED THIS WEEK | L29: ADVANCES THIS WEEK | O29: OWED NOW | R29: STATUS
B30: =IF(Workers!$B$6<>"",Workers!$B$6,"") -> Davlatbek | F30: {=IF($B30="","",IF($T$3=0,0,INDEX(Weeks!$L$7:$W$59,$T$3,1)))} -> 6 | I30: {=IF($B30="","",IF($T$3=0,0,INDEX(Weeks!$X$7:$AI$59,$T$3,1)))} -> 1482125 | L30: =IF($B30="","",SUMIFS('Cash Ledger'!$E$7:$E$1006,'Cash Ledger'!$I$7:$I$1006,Workers!$A$6,'Cash Ledger'!$D$7:$D$1006,"Advance",'Cash Ledger'!$B$7:$B$1006,">="&$R$3,'Cash Ledger'!$B$7:$B$1006,"<="&($R$3+6))) -> 150000 | O30: {=IF($B30="","",SUMPRODUCT((Weeks!$A$7:$A$59<=$R$3)*(Weeks!$X$5:$AI$5=Workers!$A$6)*Weeks!$X$7:$AI$59)-SUMIFS('Cash Ledger'!$E$7:$E$1006,'Cash Ledger'!$I$7:$I$1006,Workers!$A$6))} -> 1332125 | R30: =IF($B30="","",IF(Workers!$C$6="Left","Left",IF(ROUND($O30,0)>0,"To pay",IF(ROUND($O30,0)<0,"Owes you","Settled")))) -> To pay
B31: =IF(Workers!$B$7<>"",Workers!$B$7,"") -> Xusanboy | F31: {=IF($B31="","",IF($T$3=0,0,INDEX(Weeks!$L$7:$W$59,$T$3,2)))} -> 6 | I31: {=IF($B31="","",IF($T$3=0,0,INDEX(Weeks!$X$7:$AI$59,$T$3,2)))} -> 1482125 | L31: =IF($B31="","",SUMIFS('Cash Ledger'!$E$7:$E$1006,'Cash Ledger'!$I$7:$I$1006,Workers!$A$7,'Cash Ledger'!$D$7:$D$1006,"Advance",'Cash Ledger'!$B$7:$B$1006,">="&$R$3,'Cash Ledger'!$B$7:$B$1006,"<="&($R$3+6))) -> 500000 | O31: {=IF($B31="","",SUMPRODUCT((Weeks!$A$7:$A$59<=$R$3)*(Weeks!$X$5:$AI$5=Workers!$A$7)*Weeks!$X$7:$AI$59)-SUMIFS('Cash Ledger'!$E$7:$E$1006,'Cash Ledger'!$I$7:$I$1006,Workers!$A$7))} -> 982125 | R31: =IF($B31="","",IF(Workers!$C$7="Left","Left",IF(ROUND($O31,0)>0,"To pay",IF(ROUND($O31,0)<0,"Owes you","Settled")))) -> To pay
B32: =IF(Workers!$B$8<>"",Workers!$B$8,"") -> Oybek | F32: {=IF($B32="","",IF($T$3=0,0,INDEX(Weeks!$L$7:$W$59,$T$3,3)))} -> 6 | I32: {=IF($B32="","",IF($T$3=0,0,INDEX(Weeks!$X$7:$AI$59,$T$3,3)))} -> 1482125 | L32: =IF($B32="","",SUMIFS('Cash Ledger'!$E$7:$E$1006,'Cash Ledger'!$I$7:$I$1006,Workers!$A$8,'Cash Ledger'!$D$7:$D$1006,"Advance",'Cash Ledger'!$B$7:$B$1006,">="&$R$3,'Cash Ledger'!$B$7:$B$1006,"<="&($R$3+6))) -> 0 | O32: {=IF($B32="","",SUMPRODUCT((Weeks!$A$7:$A$59<=$R$3)*(Weeks!$X$5:$AI$5=Workers!$A$8)*Weeks!$X$7:$AI$59)-SUMIFS('Cash Ledger'!$E$7:$E$1006,'Cash Ledger'!$I$7:$I$1006,Workers!$A$8))} -> 1482125 | R32: =IF($B32="","",IF(Workers!$C$8="Left","Left",IF(ROUND($O32,0)>0,"To pay",IF(ROUND($O32,0)<0,"Owes you","Settled")))) -> To pay
B33: =IF(Workers!$B$9<>"",Workers!$B$9,"") -> Abdurashid | F33: {=IF($B33="","",IF($T$3=0,0,INDEX(Weeks!$L$7:$W$59,$T$3,4)))} -> 6 | I33: {=IF($B33="","",IF($T$3=0,0,INDEX(Weeks!$X$7:$AI$59,$T$3,4)))} -> 1482125 | L33: =IF($B33="","",SUMIFS('Cash Ledger'!$E$7:$E$1006,'Cash Ledger'!$I$7:$I$1006,Workers!$A$9,'Cash Ledger'!$D$7:$D$1006,"Advance",'Cash Ledger'!$B$7:$B$1006,">="&$R$3,'Cash Ledger'!$B$7:$B$1006,"<="&($R$3+6))) -> 0 | O33: {=IF($B33="","",SUMPRODUCT((Weeks!$A$7:$A$59<=$R$3)*(Weeks!$X$5:$AI$5=Workers!$A$9)*Weeks!$X$7:$AI$59)-SUMIFS('Cash Ledger'!$E$7:$E$1006,'Cash Ledger'!$I$7:$I$1006,Workers!$A$9))} -> 1482125 | R33: =IF($B33="","",IF(Workers!$C$9="Left","Left",IF(ROUND($O33,0)>0,"To pay",IF(ROUND($O33,0)<0,"Owes you","Settled")))) -> To pay
B34: =IF(Workers!$B$10<>"",Workers!$B$10,"") | F34: {=IF($B34="","",IF($T$3=0,0,INDEX(Weeks!$L$7:$W$59,$T$3,5)))} | I34: {=IF($B34="","",IF($T$3=0,0,INDEX(Weeks!$X$7:$AI$59,$T$3,5)))} | L34: =IF($B34="","",SUMIFS('Cash Ledger'!$E$7:$E$1006,'Cash Ledger'!$I$7:$I$1006,Workers!$A$10,'Cash Ledger'!$D$7:$D$1006,"Advance",'Cash Ledger'!$B$7:$B$1006,">="&$R$3,'Cash Ledger'!$B$7:$B$1006,"<="&($R$3+6))) | O34: {=IF($B34="","",SUMPRODUCT((Weeks!$A$7:$A$59<=$R$3)*(Weeks!$X$5:$AI$5=Workers!$A$10)*Weeks!$X$7:$AI$59)-SUMIFS('Cash Ledger'!$E$7:$E$1006,'Cash Ledger'!$I$7:$I$1006,Workers!$A$10))} | R34: =IF($B34="","",IF(Workers!$C$10="Left","Left",IF(ROUND($O34,0)>0,"To pay",IF(ROUND($O34,0)<0,"Owes you","Settled"))))
B35: =IF(Workers!$B$11<>"",Workers!$B$11,"") | F35: {=IF($B35="","",IF($T$3=0,0,INDEX(Weeks!$L$7:$W$59,$T$3,6)))} | I35: {=IF($B35="","",IF($T$3=0,0,INDEX(Weeks!$X$7:$AI$59,$T$3,6)))} | L35: =IF($B35="","",SUMIFS('Cash Ledger'!$E$7:$E$1006,'Cash Ledger'!$I$7:$I$1006,Workers!$A$11,'Cash Ledger'!$D$7:$D$1006,"Advance",'Cash Ledger'!$B$7:$B$1006,">="&$R$3,'Cash Ledger'!$B$7:$B$1006,"<="&($R$3+6))) | O35: {=IF($B35="","",SUMPRODUCT((Weeks!$A$7:$A$59<=$R$3)*(Weeks!$X$5:$AI$5=Workers!$A$11)*Weeks!$X$7:$AI$59)-SUMIFS('Cash Ledger'!$E$7:$E$1006,'Cash Ledger'!$I$7:$I$1006,Workers!$A$11))} | R35: =IF($B35="","",IF(Workers!$C$11="Left","Left",IF(ROUND($O35,0)>0,"To pay",IF(ROUND($O35,0)<0,"Owes you","Settled"))))
B36: =IF(Workers!$B$12<>"",Workers!$B$12,"") | F36: {=IF($B36="","",IF($T$3=0,0,INDEX(Weeks!$L$7:$W$59,$T$3,7)))} | I36: {=IF($B36="","",IF($T$3=0,0,INDEX(Weeks!$X$7:$AI$59,$T$3,7)))} | L36: =IF($B36="","",SUMIFS('Cash Ledger'!$E$7:$E$1006,'Cash Ledger'!$I$7:$I$1006,Workers!$A$12,'Cash Ledger'!$D$7:$D$1006,"Advance",'Cash Ledger'!$B$7:$B$1006,">="&$R$3,'Cash Ledger'!$B$7:$B$1006,"<="&($R$3+6))) | O36: {=IF($B36="","",SUMPRODUCT((Weeks!$A$7:$A$59<=$R$3)*(Weeks!$X$5:$AI$5=Workers!$A$12)*Weeks!$X$7:$AI$59)-SUMIFS('Cash Ledger'!$E$7:$E$1006,'Cash Ledger'!$I$7:$I$1006,Workers!$A$12))} | R36: =IF($B36="","",IF(Workers!$C$12="Left","Left",IF(ROUND($O36,0)>0,"To pay",IF(ROUND($O36,0)<0,"Owes you","Settled"))))
B37: =IF(Workers!$B$13<>"",Workers!$B$13,"") | F37: {=IF($B37="","",IF($T$3=0,0,INDEX(Weeks!$L$7:$W$59,$T$3,8)))} | I37: {=IF($B37="","",IF($T$3=0,0,INDEX(Weeks!$X$7:$AI$59,$T$3,8)))} | L37: =IF($B37="","",SUMIFS('Cash Ledger'!$E$7:$E$1006,'Cash Ledger'!$I$7:$I$1006,Workers!$A$13,'Cash Ledger'!$D$7:$D$1006,"Advance",'Cash Ledger'!$B$7:$B$1006,">="&$R$3,'Cash Ledger'!$B$7:$B$1006,"<="&($R$3+6))) | O37: {=IF($B37="","",SUMPRODUCT((Weeks!$A$7:$A$59<=$R$3)*(Weeks!$X$5:$AI$5=Workers!$A$13)*Weeks!$X$7:$AI$59)-SUMIFS('Cash Ledger'!$E$7:$E$1006,'Cash Ledger'!$I$7:$I$1006,Workers!$A$13))} | R37: =IF($B37="","",IF(Workers!$C$13="Left","Left",IF(ROUND($O37,0)>0,"To pay",IF(ROUND($O37,0)<0,"Owes you","Settled"))))
B38: =IF(Workers!$B$14<>"",Workers!$B$14,"") | F38: {=IF($B38="","",IF($T$3=0,0,INDEX(Weeks!$L$7:$W$59,$T$3,9)))} | I38: {=IF($B38="","",IF($T$3=0,0,INDEX(Weeks!$X$7:$AI$59,$T$3,9)))} | L38: =IF($B38="","",SUMIFS('Cash Ledger'!$E$7:$E$1006,'Cash Ledger'!$I$7:$I$1006,Workers!$A$14,'Cash Ledger'!$D$7:$D$1006,"Advance",'Cash Ledger'!$B$7:$B$1006,">="&$R$3,'Cash Ledger'!$B$7:$B$1006,"<="&($R$3+6))) | O38: {=IF($B38="","",SUMPRODUCT((Weeks!$A$7:$A$59<=$R$3)*(Weeks!$X$5:$AI$5=Workers!$A$14)*Weeks!$X$7:$AI$59)-SUMIFS('Cash Ledger'!$E$7:$E$1006,'Cash Ledger'!$I$7:$I$1006,Workers!$A$14))} | R38: =IF($B38="","",IF(Workers!$C$14="Left","Left",IF(ROUND($O38,0)>0,"To pay",IF(ROUND($O38,0)<0,"Owes you","Settled"))))
B39: =IF(Workers!$B$15<>"",Workers!$B$15,"") | F39: {=IF($B39="","",IF($T$3=0,0,INDEX(Weeks!$L$7:$W$59,$T$3,10)))} | I39: {=IF($B39="","",IF($T$3=0,0,INDEX(Weeks!$X$7:$AI$59,$T$3,10)))} | L39: =IF($B39="","",SUMIFS('Cash Ledger'!$E$7:$E$1006,'Cash Ledger'!$I$7:$I$1006,Workers!$A$15,'Cash Ledger'!$D$7:$D$1006,"Advance",'Cash Ledger'!$B$7:$B$1006,">="&$R$3,'Cash Ledger'!$B$7:$B$1006,"<="&($R$3+6))) | O39: {=IF($B39="","",SUMPRODUCT((Weeks!$A$7:$A$59<=$R$3)*(Weeks!$X$5:$AI$5=Workers!$A$15)*Weeks!$X$7:$AI$59)-SUMIFS('Cash Ledger'!$E$7:$E$1006,'Cash Ledger'!$I$7:$I$1006,Workers!$A$15))} | R39: =IF($B39="","",IF(Workers!$C$15="Left","Left",IF(ROUND($O39,0)>0,"To pay",IF(ROUND($O39,0)<0,"Owes you","Settled"))))
B40: =IF(Workers!$B$16<>"",Workers!$B$16,"") | F40: {=IF($B40="","",IF($T$3=0,0,INDEX(Weeks!$L$7:$W$59,$T$3,11)))} | I40: {=IF($B40="","",IF($T$3=0,0,INDEX(Weeks!$X$7:$AI$59,$T$3,11)))} | L40: =IF($B40="","",SUMIFS('Cash Ledger'!$E$7:$E$1006,'Cash Ledger'!$I$7:$I$1006,Workers!$A$16,'Cash Ledger'!$D$7:$D$1006,"Advance",'Cash Ledger'!$B$7:$B$1006,">="&$R$3,'Cash Ledger'!$B$7:$B$1006,"<="&($R$3+6))) | O40: {=IF($B40="","",SUMPRODUCT((Weeks!$A$7:$A$59<=$R$3)*(Weeks!$X$5:$AI$5=Workers!$A$16)*Weeks!$X$7:$AI$59)-SUMIFS('Cash Ledger'!$E$7:$E$1006,'Cash Ledger'!$I$7:$I$1006,Workers!$A$16))} | R40: =IF($B40="","",IF(Workers!$C$16="Left","Left",IF(ROUND($O40,0)>0,"To pay",IF(ROUND($O40,0)<0,"Owes you","Settled"))))
B41: =IF(Workers!$B$17<>"",Workers!$B$17,"") | F41: {=IF($B41="","",IF($T$3=0,0,INDEX(Weeks!$L$7:$W$59,$T$3,12)))} | I41: {=IF($B41="","",IF($T$3=0,0,INDEX(Weeks!$X$7:$AI$59,$T$3,12)))} | L41: =IF($B41="","",SUMIFS('Cash Ledger'!$E$7:$E$1006,'Cash Ledger'!$I$7:$I$1006,Workers!$A$17,'Cash Ledger'!$D$7:$D$1006,"Advance",'Cash Ledger'!$B$7:$B$1006,">="&$R$3,'Cash Ledger'!$B$7:$B$1006,"<="&($R$3+6))) | O41: {=IF($B41="","",SUMPRODUCT((Weeks!$A$7:$A$59<=$R$3)*(Weeks!$X$5:$AI$5=Workers!$A$17)*Weeks!$X$7:$AI$59)-SUMIFS('Cash Ledger'!$E$7:$E$1006,'Cash Ledger'!$I$7:$I$1006,Workers!$A$17))} | R41: =IF($B41="","",IF(Workers!$C$17="Left","Left",IF(ROUND($O41,0)>0,"To pay",IF(ROUND($O41,0)<0,"Owes you","Settled"))))
B42: =IF(COUNTA(Workers!$B$6:$B$17)<12,"+ add another worker on the Workers page","") -> + add another worker on the Workers page
B44: Donabay · block plant payroll · type only in the tinted cells on each page

Sheet Daily Log
A1: ◆ Donabay | D1: Home | F1: Daily Log | G1: Cash Ledger | I1: Weekly Pay | K1: Payslip | X1: Workers | Y1: Settings | AA1: Guide | AC1: · | AD1: History | AF1: Weeks | AH1: Checks
A2: Daily Log
A3: One row per day. Fill: blocks moulded, blocks broken, and who worked (1 = full day, 0.5 = half day, empty = absent).
A4: All time | C4: =SUM(C7:C377) -> 11978 | D4: =SUM(D7:D377) -> 121 | E4: =SUM(E7:E377) -> 11857 | F4: =SUM(F7:F377) -> 11857 | G4: Attendance: 1 full day, 0.5 half day, empty = absent | U4: =SUM(U7:U377) -> 5928500
A5: Today's row is green · Ctrl+↓ jumps down | G5: =IF(Workers!$B$6="","",Workers!$B$6) -> Davlatbek | H5: =IF(Workers!$B$7="","",Workers!$B$7) -> Xusanboy | I5: =IF(Workers!$B$8="","",Workers!$B$8) -> Oybek | J5: =IF(Workers!$B$9="","",Workers!$B$9) -> Abdurashid | K5: =IF(Workers!$B$10="","",Workers!$B$10) | L5: =IF(Workers!$B$11="","",Workers!$B$11) | M5: =IF(Workers!$B$12="","",Workers!$B$12) | N5: =IF(Workers!$B$13="","",Workers!$B$13) | O5: =IF(Workers!$B$14="","",Workers!$B$14) | P5: =IF(Workers!$B$15="","",Workers!$B$15) | Q5: =IF(Workers!$B$16="","",Workers!$B$16) | R5: =IF(Workers!$B$17="","",Workers!$B$17)
A6: Date | B6: Day | C6: Moulded | D6: Broken | E6: Good | F6: Paid blocks | G6: =IF(Workers!$B$6="",Workers!$A$6,Workers!$B$6) -> Davlatbek | H6: =IF(Workers!$B$7="",Workers!$A$7,Workers!$B$7) -> Xusanboy | I6: =IF(Workers!$B$8="",Workers!$A$8,Workers!$B$8) -> Oybek | J6: =IF(Workers!$B$9="",Workers!$A$9,Workers!$B$9) -> Abdurashid | K6: =IF(Workers!$B$10="",Workers!$A$10,Workers!$B$10) -> W05 | L6: =IF(Workers!$B$11="",Workers!$A$11,Workers!$B$11) -> W06 | M6: =IF(Workers!$B$12="",Workers!$A$12,Workers!$B$12) -> W07 | N6: =IF(Workers!$B$13="",Workers!$A$13,Workers!$B$13) -> W08 | O6: =IF(Workers!$B$14="",Workers!$A$14,Workers!$B$14) -> W09 | P6: =IF(Workers!$B$15="",Workers!$A$15,Workers!$B$15) -> W10 | Q6: =IF(Workers!$B$16="",Workers!$A$16,Workers!$B$16) -> W11 | R6: =IF(Workers!$B$17="",Workers!$A$17,Workers!$B$17) -> W12 | S6: Crew-days | T6: Rate | U6: Pay value | V6: Week of | W6: Check | X6: Notes
A7: 46286 | B7: =CHOOSE(WEEKDAY($A7,2),"Mon","Tue","Wed","Thu","Fri","Sat","Sun") -> Mon | C7: 1500 | D7: 10 | E7: =IF($C7="","",$C7-N($D7)) -> 1490 | F7: =IF($C7="","",$C7-MAX(0,N($D7)-BreakAllow*$C7)) -> 1490 | G7: 1 | H7: 1 | I7: 1 | J7: 1 | S7: =IF(COUNT(G7:R7)=0,"",SUM(G7:R7)) -> 4 | T7: =IF($C7="","",IFERROR(INDEX(RateValues,MATCH(SUMPRODUCT(MAX((RateDates<=$A7)*RateDates)),RateDates,0)),0)) -> 500 | U7: =IF($C7="","",$F7*$T7) -> 745000 | V7: =$A7-WEEKDAY($A7,2)+1 -> 46286 | W7: {=IF(AND($C7="",S7=""),"",IF(AND(N($C7)>0,N(S7)=0),"nobody marked present",IF(N($D7)>N($C7),"more broken than moulded",IF(AND($C7="",N(S7)>0),"attendance marked but no blocks entered",IF(AND(N($C7)>0,N(T7)=0),"no pay rate for this date - see Settings",IF(SUMPRODUCT((G7:R7<>"")*(G$5:R$5=""))>0,"attendance in an empty worker slot",""))))))}
A8: 46287 | B8: =CHOOSE(WEEKDAY($A8,2),"Mon","Tue","Wed","Thu","Fri","Sat","Sun") -> Tue | C8: 2000 | D8: 21 | E8: =IF($C8="","",$C8-N($D8)) -> 1979 | F8: =IF($C8="","",$C8-MAX(0,N($D8)-BreakAllow*$C8)) -> 1979 | G8: 1 | H8: 1 | I8: 1 | J8: 1 | S8: =IF(COUNT(G8:R8)=0,"",SUM(G8:R8)) -> 4 | T8: =IF($C8="","",IFERROR(INDEX(RateValues,MATCH(SUMPRODUCT(MAX((RateDates<=$A8)*RateDates)),RateDates,0)),0)) -> 500 | U8: =IF($C8="","",$F8*$T8) -> 989500 | V8: =$A8-WEEKDAY($A8,2)+1 -> 46286 | W8: {=IF(AND($C8="",S8=""),"",IF(AND(N($C8)>0,N(S8)=0),"nobody marked present",IF(N($D8)>N($C8),"more broken than moulded",IF(AND($C8="",N(S8)>0),"attendance marked but no blocks entered",IF(AND(N($C8)>0,N(T8)=0),"no pay rate for this date - see Settings",IF(SUMPRODUCT((G8:R8<>"")*(G$5:R$5=""))>0,"attendance in an empty worker slot",""))))))}
A9: 46288 | B9: =CHOOSE(WEEKDAY($A9,2),"Mon","Tue","Wed","Thu","Fri","Sat","Sun") -> Wed | C9: 2300 | D9: 25 | E9: =IF($C9="","",$C9-N($D9)) -> 2275 | F9: =IF($C9="","",$C9-MAX(0,N($D9)-BreakAllow*$C9)) -> 2275 | G9: 1 | H9: 1 | I9: 1 | J9: 1 | S9: =IF(COUNT(G9:R9)=0,"",SUM(G9:R9)) -> 4 | T9: =IF($C9="","",IFERROR(INDEX(RateValues,MATCH(SUMPRODUCT(MAX((RateDates<=$A9)*RateDates)),RateDates,0)),0)) -> 500 | U9: =IF($C9="","",$F9*$T9) -> 1137500 | V9: =$A9-WEEKDAY($A9,2)+1 -> 46286 | W9: {=IF(AND($C9="",S9=""),"",IF(AND(N($C9)>0,N(S9)=0),"nobody marked present",IF(N($D9)>N($C9),"more broken than moulded",IF(AND($C9="",N(S9)>0),"attendance marked but no blocks entered",IF(AND(N($C9)>0,N(T9)=0),"no pay rate for this date - see Settings",IF(SUMPRODUCT((G9:R9<>"")*(G$5:R$5=""))>0,"attendance in an empty worker slot",""))))))}
A10: 46289 | B10: =CHOOSE(WEEKDAY($A10,2),"Mon","Tue","Wed","Thu","Fri","Sat","Sun") -> Thu | C10: 1900 | D10: 20 | E10: =IF($C10="","",$C10-N($D10)) -> 1880 | F10: =IF($C10="","",$C10-MAX(0,N($D10)-BreakAllow*$C10)) -> 1880 | G10: 1 | H10: 1 | I10: 1 | J10: 1 | S10: =IF(COUNT(G10:R10)=0,"",SUM(G10:R10)) -> 4 | T10: =IF($C10="","",IFERROR(INDEX(RateValues,MATCH(SUMPRODUCT(MAX((RateDates<=$A10)*RateDates)),RateDates,0)),0)) -> 500 | U10: =IF($C10="","",$F10*$T10) -> 940000 | V10: =$A10-WEEKDAY($A10,2)+1 -> 46286 | W10: {=IF(AND($C10="",S10=""),"",IF(AND(N($C10)>0,N(S10)=0),"nobody marked present",IF(N($D10)>N($C10),"more broken than moulded",IF(AND($C10="",N(S10)>0),"attendance marked but no blocks entered",IF(AND(N($C10)>0,N(T10)=0),"no pay rate for this date - see Settings",IF(SUMPRODUCT((G10:R10<>"")*(G$5:R$5=""))>0,"attendance in an empty worker slot",""))))))}
A11: 46290 | B11: =CHOOSE(WEEKDAY($A11,2),"Mon","Tue","Wed","Thu","Fri","Sat","Sun") -> Fri | C11: 2278 | D11: 25 | E11: =IF($C11="","",$C11-N($D11)) -> 2253 | F11: =IF($C11="","",$C11-MAX(0,N($D11)-BreakAllow*$C11)) -> 2253 | G11: 1 | H11: 1 | I11: 1 | J11: 1 | S11: =IF(COUNT(G11:R11)=0,"",SUM(G11:R11)) -> 4 | T11: =IF($C11="","",IFERROR(INDEX(RateValues,MATCH(SUMPRODUCT(MAX((RateDates<=$A11)*RateDates)),RateDates,0)),0)) -> 500 | U11: =IF($C11="","",$F11*$T11) -> 1126500 | V11: =$A11-WEEKDAY($A11,2)+1 -> 46286 | W11: {=IF(AND($C11="",S11=""),"",IF(AND(N($C11)>0,N(S11)=0),"nobody marked present",IF(N($D11)>N($C11),"more broken than moulded",IF(AND($C11="",N(S11)>0),"attendance marked but no blocks entered",IF(AND(N($C11)>0,N(T11)=0),"no pay rate for this date - see Settings",IF(SUMPRODUCT((G11:R11<>"")*(G$5:R$5=""))>0,"attendance in an empty worker slot",""))))))}
A12: 46291 | B12: =CHOOSE(WEEKDAY($A12,2),"Mon","Tue","Wed","Thu","Fri","Sat","Sun") -> Sat | C12: 2000 | D12: 20 | E12: =IF($C12="","",$C12-N($D12)) -> 1980 | F12: =IF($C12="","",$C12-MAX(0,N($D12)-BreakAllow*$C12)) -> 1980 | G12: 1 | H12: 1 | I12: 1 | J12: 1 | S12: =IF(COUNT(G12:R12)=0,"",SUM(G12:R12)) -> 4 | T12: =IF($C12="","",IFERROR(INDEX(RateValues,MATCH(SUMPRODUCT(MAX((RateDates<=$A12)*RateDates)),RateDates,0)),0)) -> 500 | U12: =IF($C12="","",$F12*$T12) -> 990000 | V12: =$A12-WEEKDAY($A12,2)+1 -> 46286 | W12: {=IF(AND($C12="",S12=""),"",IF(AND(N($C12)>0,N(S12)=0),"nobody marked present",IF(N($D12)>N($C12),"more broken than moulded",IF(AND($C12="",N(S12)>0),"attendance marked but no blocks entered",IF(AND(N($C12)>0,N(T12)=0),"no pay rate for this date - see Settings",IF(SUMPRODUCT((G12:R12<>"")*(G$5:R$5=""))>0,"attendance in an empty worker slot",""))))))}
A13: 46292 | B13: =CHOOSE(WEEKDAY($A13,2),"Mon","Tue","Wed","Thu","Fri","Sat","Sun") -> Sun | E13: =IF($C13="","",$C13-N($D13)) | F13: =IF($C13="","",$C13-MAX(0,N($D13)-BreakAllow*$C13)) | S13: =IF(COUNT(G13:R13)=0,"",SUM(G13:R13)) | T13: =IF($C13="","",IFERROR(INDEX(RateValues,MATCH(SUMPRODUCT(MAX((RateDates<=$A13)*RateDates)),RateDates,0)),0)) | U13: =IF($C13="","",$F13*$T13) | V13: =$A13-WEEKDAY($A13,2)+1 -> 46286 | W13: {=IF(AND($C13="",S13=""),"",IF(AND(N($C13)>0,N(S13)=0),"nobody marked present",IF(N($D13)>N($C13),"more broken than moulded",IF(AND($C13="",N(S13)>0),"attendance marked but no blocks entered",IF(AND(N($C13)>0,N(T13)=0),"no pay rate for this date - see Settings",IF(SUMPRODUCT((G13:R13<>"")*(G$5:R$5=""))>0,"attendance in an empty worker slot",""))))))}
A14: 46293 | B14: =CHOOSE(WEEKDAY($A14,2),"Mon","Tue","Wed","Thu","Fri","Sat","Sun") -> Mon | E14: =IF($C14="","",$C14-N($D14)) | F14: =IF($C14="","",$C14-MAX(0,N($D14)-BreakAllow*$C14)) | S14: =IF(COUNT(G14:R14)=0,"",SUM(G14:R14)) | T14: =IF($C14="","",IFERROR(INDEX(RateValues,MATCH(SUMPRODUCT(MAX((RateDates<=$A14)*RateDates)),RateDates,0)),0)) | U14: =IF($C14="","",$F14*$T14) | V14: =$A14-WEEKDAY($A14,2)+1 -> 46293 | W14: {=IF(AND($C14="",S14=""),"",IF(AND(N($C14)>0,N(S14)=0),"nobody marked present",IF(N($D14)>N($C14),"more broken than moulded",IF(AND($C14="",N(S14)>0),"attendance marked but no blocks entered",IF(AND(N($C14)>0,N(T14)=0),"no pay rate for this date - see Settings",IF(SUMPRODUCT((G14:R14<>"")*(G$5:R$5=""))>0,"attendance in an empty worker slot",""))))))}
A15: 46294 | B15: =CHOOSE(WEEKDAY($A15,2),"Mon","Tue","Wed","Thu","Fri","Sat","Sun") -> Tue | E15: =IF($C15="","",$C15-N($D15)) | F15: =IF($C15="","",$C15-MAX(0,N($D15)-BreakAllow*$C15)) | S15: =IF(COUNT(G15:R15)=0,"",SUM(G15:R15)) | T15: =IF($C15="","",IFERROR(INDEX(RateValues,MATCH(SUMPRODUCT(MAX((RateDates<=$A15)*RateDates)),RateDates,0)),0)) | U15: =IF($C15="","",$F15*$T15) | V15: =$A15-WEEKDAY($A15,2)+1 -> 46293 | W15: {=IF(AND($C15="",S15=""),"",IF(AND(N($C15)>0,N(S15)=0),"nobody marked present",IF(N($D15)>N($C15),"more broken than moulded",IF(AND($C15="",N(S15)>0),"attendance marked but no blocks entered",IF(AND(N($C15)>0,N(T15)=0),"no pay rate for this date - see Settings",IF(SUMPRODUCT((G15:R15<>"")*(G$5:R$5=""))>0,"attendance in an empty worker slot",""))))))}
A16: 46295 | B16: =CHOOSE(WEEKDAY($A16,2),"Mon","Tue","Wed","Thu","Fri","Sat","Sun") -> Wed | E16: =IF($C16="","",$C16-N($D16)) | F16: =IF($C16="","",$C16-MAX(0,N($D16)-BreakAllow*$C16)) | S16: =IF(COUNT(G16:R16)=0,"",SUM(G16:R16)) | T16: =IF($C16="","",IFERROR(INDEX(RateValues,MATCH(SUMPRODUCT(MAX((RateDates<=$A16)*RateDates)),RateDates,0)),0)) | U16: =IF($C16="","",$F16*$T16) | V16: =$A16-WEEKDAY($A16,2)+1 -> 46293 | W16: {=IF(AND($C16="",S16=""),"",IF(AND(N($C16)>0,N(S16)=0),"nobody marked present",IF(N($D16)>N($C16),"more broken than moulded",IF(AND($C16="",N(S16)>0),"attendance marked but no blocks entered",IF(AND(N($C16)>0,N(T16)=0),"no pay rate for this date - see Settings",IF(SUMPRODUCT((G16:R16<>"")*(G$5:R$5=""))>0,"attendance in an empty worker slot",""))))))}
A17: 46296 | B17: =CHOOSE(WEEKDAY($A17,2),"Mon","Tue","Wed","Thu","Fri","Sat","Sun") -> Thu | E17: =IF($C17="","",$C17-N($D17)) | F17: =IF($C17="","",$C17-MAX(0,N($D17)-BreakAllow*$C17)) | S17: =IF(COUNT(G17:R17)=0,"",SUM(G17:R17)) | T17: =IF($C17="","",IFERROR(INDEX(RateValues,MATCH(SUMPRODUCT(MAX((RateDates<=$A17)*RateDates)),RateDates,0)),0)) | U17: =IF($C17="","",$F17*$T17) | V17: =$A17-WEEKDAY($A17,2)+1 -> 46293 | W17: {=IF(AND($C17="",S17=""),"",IF(AND(N($C17)>0,N(S17)=0),"nobody marked present",IF(N($D17)>N($C17),"more broken than moulded",IF(AND($C17="",N(S17)>0),"attendance marked but no blocks entered",IF(AND(N($C17)>0,N(T17)=0),"no pay rate for this date - see Settings",IF(SUMPRODUCT((G17:R17<>"")*(G$5:R$5=""))>0,"attendance in an empty worker slot",""))))))}
A18: 46297 | B18: =CHOOSE(WEEKDAY($A18,2),"Mon","Tue","Wed","Thu","Fri","Sat","Sun") -> Fri | E18: =IF($C18="","",$C18-N($D18)) | F18: =IF($C18="","",$C18-MAX(0,N($D18)-BreakAllow*$C18)) | S18: =IF(COUNT(G18:R18)=0,"",SUM(G18:R18)) | T18: =IF($C18="","",IFERROR(INDEX(RateValues,MATCH(SUMPRODUCT(MAX((RateDates<=$A18)*RateDates)),RateDates,0)),0)) | U18: =IF($C18="","",$F18*$T18) | V18: =$A18-WEEKDAY($A18,2)+1 -> 46293 | W18: {=IF(AND($C18="",S18=""),"",IF(AND(N($C18)>0,N(S18)=0),"nobody marked present",IF(N($D18)>N($C18),"more broken than moulded",IF(AND($C18="",N(S18)>0),"attendance marked but no blocks entered",IF(AND(N($C18)>0,N(T18)=0),"no pay rate for this date - see Settings",IF(SUMPRODUCT((G18:R18<>"")*(G$5:R$5=""))>0,"attendance in an empty worker slot",""))))))}
A19: 46298 | B19: =CHOOSE(WEEKDAY($A19,2),"Mon","Tue","Wed","Thu","Fri","Sat","Sun") -> Sat | E19: =IF($C19="","",$C19-N($D19)) | F19: =IF($C19="","",$C19-MAX(0,N($D19)-BreakAllow*$C19)) | S19: =IF(COUNT(G19:R19)=0,"",SUM(G19:R19)) | T19: =IF($C19="","",IFERROR(INDEX(RateValues,MATCH(SUMPRODUCT(MAX((RateDates<=$A19)*RateDates)),RateDates,0)),0)) | U19: =IF($C19="","",$F19*$T19) | V19: =$A19-WEEKDAY($A19,2)+1 -> 46293 | W19: {=IF(AND($C19="",S19=""),"",IF(AND(N($C19)>0,N(S19)=0),"nobody marked present",IF(N($D19)>N($C19),"more broken than moulded",IF(AND($C19="",N(S19)>0),"attendance marked but no blocks entered",IF(AND(N($C19)>0,N(T19)=0),"no pay rate for this date - see Settings",IF(SUMPRODUCT((G19:R19<>"")*(G$5:R$5=""))>0,"attendance in an empty worker slot",""))))))}
A20: 46299 | B20: =CHOOSE(WEEKDAY($A20,2),"Mon","Tue","Wed","Thu","Fri","Sat","Sun") -> Sun | E20: =IF($C20="","",$C20-N($D20)) | F20: =IF($C20="","",$C20-MAX(0,N($D20)-BreakAllow*$C20)) | S20: =IF(COUNT(G20:R20)=0,"",SUM(G20:R20)) | T20: =IF($C20="","",IFERROR(INDEX(RateValues,MATCH(SUMPRODUCT(MAX((RateDates<=$A20)*RateDates)),RateDates,0)),0)) | U20: =IF($C20="","",$F20*$T20) | V20: =$A20-WEEKDAY($A20,2)+1 -> 46293 | W20: {=IF(AND($C20="",S20=""),"",IF(AND(N($C20)>0,N(S20)=0),"nobody marked present",IF(N($D20)>N($C20),"more broken than moulded",IF(AND($C20="",N(S20)>0),"attendance marked but no blocks entered",IF(AND(N($C20)>0,N(T20)=0),"no pay rate for this date - see Settings",IF(SUMPRODUCT((G20:R20<>"")*(G$5:R$5=""))>0,"attendance in an empty worker slot",""))))))}
A21: 46300 | B21: =CHOOSE(WEEKDAY($A21,2),"Mon","Tue","Wed","Thu","Fri","Sat","Sun") -> Mon | E21: =IF($C21="","",$C21-N($D21)) | F21: =IF($C21="","",$C21-MAX(0,N($D21)-BreakAllow*$C21)) | S21: =IF(COUNT(G21:R21)=0,"",SUM(G21:R21)) | T21: =IF($C21="","",IFERROR(INDEX(RateValues,MATCH(SUMPRODUCT(MAX((RateDates<=$A21)*RateDates)),RateDates,0)),0)) | U21: =IF($C21="","",$F21*$T21) | V21: =$A21-WEEKDAY($A21,2)+1 -> 46300 | W21: {=IF(AND($C21="",S21=""),"",IF(AND(N($C21)>0,N(S21)=0),"nobody marked present",IF(N($D21)>N($C21),"more broken than moulded",IF(AND($C21="",N(S21)>0),"attendance marked but no blocks entered",IF(AND(N($C21)>0,N(T21)=0),"no pay rate for this date - see Settings",IF(SUMPRODUCT((G21:R21<>"")*(G$5:R$5=""))>0,"attendance in an empty worker slot",""))))))}
A22: 46301 | B22: =CHOOSE(WEEKDAY($A22,2),"Mon","Tue","Wed","Thu","Fri","Sat","Sun") -> Tue | E22: =IF($C22="","",$C22-N($D22)) | F22: =IF($C22="","",$C22-MAX(0,N($D22)-BreakAllow*$C22)) | S22: =IF(COUNT(G22:R22)=0,"",SUM(G22:R22)) | T22: =IF($C22="","",IFERROR(INDEX(RateValues,MATCH(SUMPRODUCT(MAX((RateDates<=$A22)*RateDates)),RateDates,0)),0)) | U22: =IF($C22="","",$F22*$T22) | V22: =$A22-WEEKDAY($A22,2)+1 -> 46300 | W22: {=IF(AND($C22="",S22=""),"",IF(AND(N($C22)>0,N(S22)=0),"nobody marked present",IF(N($D22)>N($C22),"more broken than moulded",IF(AND($C22="",N(S22)>0),"attendance marked but no blocks entered",IF(AND(N($C22)>0,N(T22)=0),"no pay rate for this date - see Settings",IF(SUMPRODUCT((G22:R22<>"")*(G$5:R$5=""))>0,"attendance in an empty worker slot",""))))))}
A23: 46302 | B23: =CHOOSE(WEEKDAY($A23,2),"Mon","Tue","Wed","Thu","Fri","Sat","Sun") -> Wed | E23: =IF($C23="","",$C23-N($D23)) | F23: =IF($C23="","",$C23-MAX(0,N($D23)-BreakAllow*$C23)) | S23: =IF(COUNT(G23:R23)=0,"",SUM(G23:R23)) | T23: =IF($C23="","",IFERROR(INDEX(RateValues,MATCH(SUMPRODUCT(MAX((RateDates<=$A23)*RateDates)),RateDates,0)),0)) | U23: =IF($C23="","",$F23*$T23) | V23: =$A23-WEEKDAY($A23,2)+1 -> 46300 | W23: {=IF(AND($C23="",S23=""),"",IF(AND(N($C23)>0,N(S23)=0),"nobody marked present",IF(N($D23)>N($C23),"more broken than moulded",IF(AND($C23="",N(S23)>0),"attendance marked but no blocks entered",IF(AND(N($C23)>0,N(T23)=0),"no pay rate for this date - see Settings",IF(SUMPRODUCT((G23:R23<>"")*(G$5:R$5=""))>0,"attendance in an empty worker slot",""))))))}
A24: 46303 | B24: =CHOOSE(WEEKDAY($A24,2),"Mon","Tue","Wed","Thu","Fri","Sat","Sun") -> Thu | E24: =IF($C24="","",$C24-N($D24)) | F24: =IF($C24="","",$C24-MAX(0,N($D24)-BreakAllow*$C24)) | S24: =IF(COUNT(G24:R24)=0,"",SUM(G24:R24)) | T24: =IF($C24="","",IFERROR(INDEX(RateValues,MATCH(SUMPRODUCT(MAX((RateDates<=$A24)*RateDates)),RateDates,0)),0)) | U24: =IF($C24="","",$F24*$T24) | V24: =$A24-WEEKDAY($A24,2)+1 -> 46300 | W24: {=IF(AND($C24="",S24=""),"",IF(AND(N($C24)>0,N(S24)=0),"nobody marked present",IF(N($D24)>N($C24),"more broken than moulded",IF(AND($C24="",N(S24)>0),"attendance marked but no blocks entered",IF(AND(N($C24)>0,N(T24)=0),"no pay rate for this date - see Settings",IF(SUMPRODUCT((G24:R24<>"")*(G$5:R$5=""))>0,"attendance in an empty worker slot",""))))))}
... A377: 46656 | B377: =CHOOSE(WEEKDAY($A377,2),"Mon","Tue","Wed","Thu","Fri","Sat","Sun") -> Sun | E377: =IF($C377="","",$C377-N($D377)) | F377: =IF($C377="","",$C377-MAX(0,N($D377)-BreakAllow*$C377)) | S377: =IF(COUNT(G377:R377)=0,"",SUM(G377:R377)) | T377: =IF($C377="","",IFERROR(INDEX(RateValues,MATCH(SUMPRODUCT(MAX((RateDates<=$A377)*RateDates)),RateDates,0)),0)) | U377: =IF($C377="","",$F377*$T377) | V377: =$A377-WEEKDAY($A377,2)+1 -> 46650 | W377: {=IF(AND($C377="",S377=""),"",IF(AND(N($C377)>0,N(S377)=0),"nobody marked present",IF(N($D377)>N($C377),"more broken than moulded",IF(AND($C377="",N(S377)>0),"attendance marked but no blocks entered",IF(AND(N($C377)>0,N(T377)=0),"no pay rate for this date - see Settings",IF(SUMPRODUCT((G377:R377<>"")*(G$5:R$5=""))>0,"attendance in an empty worker slot",""))))))}

Sheet Cash Ledger
A1: ◆ Donabay | D1: Home | E1: Daily Log | G1: Cash Ledger | I1: Weekly Pay | N1: Payslip | P1: Workers | R1: Settings | T1: Guide | V1: · | W1: History | Y1: Weeks | AA1: Checks
A2: Cash Ledger
A3: Every som you hand a worker goes here - one row each time. Never delete a row: fix a mistake with a Correction.
C4: Totals | D4: Advances | E4: =SUMIFS($E$7:$E$1006,$D$7:$D$1006,"Advance") -> 650000 | F4: Weekly pay | G4: =SUMIFS($E$7:$E$1006,$D$7:$D$1006,"Weekly pay") -> 0 | L4: Corrections | M4: =SUMIFS($E$7:$E$1006,$D$7:$D$1006,"Correction") -> 0
A5: Tips: Ctrl+; types today's date · click B7 then Ctrl+↓ to jump to the last entry
A6: # | B6: Date | C6: Worker | D6: Type | E6: Amount (so'm) | F6: Reason | G6: Given by | H6: Signed? | I6: ID | J6: Week of | K6: key | L6: Worker balance after | M6: Check
A7: =IF($B7="","",ROW()-6) -> 1 | B7: 46286 | C7: Davlatbek | D7: Advance | E7: 150000 | F7: Karta | I7: =IF($C7="","",IFERROR(INDEX(WorkerIDs,MATCH($C7,WorkerNames,0)),"?")) -> W01 | J7: =IF($B7="","",$B7-WEEKDAY($B7,2)+1) -> 46286 | K7: =IF(OR($I7="",$I7="?",$D7<>"Advance",$B7=""),"",$I7&"|"&$J7&"|"&COUNTIFS($I$7:$I7,$I7,$J$7:$J7,$J7,$D$7:$D7,"Advance")) -> W01|46286|1 | L7: =IF(OR($I7="",$I7="?",$B7=""),"",SUMPRODUCT((Weeks!$A$7:$A$59<=$J7)*(Weeks!$X$5:$AI$5=$I7)*Weeks!$X$7:$AI$59)-SUMIFS($E$7:$E$1006,$I$7:$I$1006,$I7,$B$7:$B$1006,"<="&$B7)) -> 1332125 | M7: =IF($B7&$C7&$D7&$E7="","",IF($B7="","missing date",IF($C7="","missing worker",IF($I7="?","unknown worker - was the name changed on Workers?",IF($D7="","missing type",IF(N($E7)=0,"missing amount",IF(AND($E7<0,$D7<>"Correction"),"negative amount - use a Correction to undo",IF(OR($B7<Weeks!$A$7,$B7>Weeks!$B$59),"date outside this workbook's year",IF(AND($D7="Advance",N($L7)<0),"Warning: more than earned so far - worker now owes "&TEXT(ROUND(-$L7,0),"#,##0"),"")))))))))
A8: =IF($B8="","",ROW()-6) -> 2 | B8: 46287 | C8: Xusanboy | D8: Advance | E8: 500000 | F8: Karta+Naqd | I8: =IF($C8="","",IFERROR(INDEX(WorkerIDs,MATCH($C8,WorkerNames,0)),"?")) -> W02 | J8: =IF($B8="","",$B8-WEEKDAY($B8,2)+1) -> 46286 | K8: =IF(OR($I8="",$I8="?",$D8<>"Advance",$B8=""),"",$I8&"|"&$J8&"|"&COUNTIFS($I$7:$I8,$I8,$J$7:$J8,$J8,$D$7:$D8,"Advance")) -> W02|46286|1 | L8: =IF(OR($I8="",$I8="?",$B8=""),"",SUMPRODUCT((Weeks!$A$7:$A$59<=$J8)*(Weeks!$X$5:$AI$5=$I8)*Weeks!$X$7:$AI$59)-SUMIFS($E$7:$E$1006,$I$7:$I$1006,$I8,$B$7:$B$1006,"<="&$B8)) -> 982125 | M8: =IF($B8&$C8&$D8&$E8="","",IF($B8="","missing date",IF($C8="","missing worker",IF($I8="?","unknown worker - was the name changed on Workers?",IF($D8="","missing type",IF(N($E8)=0,"missing amount",IF(AND($E8<0,$D8<>"Correction"),"negative amount - use a Correction to undo",IF(OR($B8<Weeks!$A$7,$B8>Weeks!$B$59),"date outside this workbook's year",IF(AND($D8="Advance",N($L8)<0),"Warning: more than earned so far - worker now owes "&TEXT(ROUND(-$L8,0),"#,##0"),"")))))))))
A9: =IF($B9="","",ROW()-6) | I9: =IF($C9="","",IFERROR(INDEX(WorkerIDs,MATCH($C9,WorkerNames,0)),"?")) | J9: =IF($B9="","",$B9-WEEKDAY($B9,2)+1) | K9: =IF(OR($I9="",$I9="?",$D9<>"Advance",$B9=""),"",$I9&"|"&$J9&"|"&COUNTIFS($I$7:$I9,$I9,$J$7:$J9,$J9,$D$7:$D9,"Advance")) | L9: =IF(OR($I9="",$I9="?",$B9=""),"",SUMPRODUCT((Weeks!$A$7:$A$59<=$J9)*(Weeks!$X$5:$AI$5=$I9)*Weeks!$X$7:$AI$59)-SUMIFS($E$7:$E$1006,$I$7:$I$1006,$I9,$B$7:$B$1006,"<="&$B9)) | M9: =IF($B9&$C9&$D9&$E9="","",IF($B9="","missing date",IF($C9="","missing worker",IF($I9="?","unknown worker - was the name changed on Workers?",IF($D9="","missing type",IF(N($E9)=0,"missing amount",IF(AND($E9<0,$D9<>"Correction"),"negative amount - use a Correction to undo",IF(OR($B9<Weeks!$A$7,$B9>Weeks!$B$59),"date outside this workbook's year",IF(AND($D9="Advance",N($L9)<0),"Warning: more than earned so far - worker now owes "&TEXT(ROUND(-$L9,0),"#,##0"),"")))))))))
A10: =IF($B10="","",ROW()-6) | I10: =IF($C10="","",IFERROR(INDEX(WorkerIDs,MATCH($C10,WorkerNames,0)),"?")) | J10: =IF($B10="","",$B10-WEEKDAY($B10,2)+1) | K10: =IF(OR($I10="",$I10="?",$D10<>"Advance",$B10=""),"",$I10&"|"&$J10&"|"&COUNTIFS($I$7:$I10,$I10,$J$7:$J10,$J10,$D$7:$D10,"Advance")) | L10: =IF(OR($I10="",$I10="?",$B10=""),"",SUMPRODUCT((Weeks!$A$7:$A$59<=$J10)*(Weeks!$X$5:$AI$5=$I10)*Weeks!$X$7:$AI$59)-SUMIFS($E$7:$E$1006,$I$7:$I$1006,$I10,$B$7:$B$1006,"<="&$B10)) | M10: =IF($B10&$C10&$D10&$E10="","",IF($B10="","missing date",IF($C10="","missing worker",IF($I10="?","unknown worker - was the name changed on Workers?",IF($D10="","missing type",IF(N($E10)=0,"missing amount",IF(AND($E10<0,$D10<>"Correction"),"negative amount - use a Correction to undo",IF(OR($B10<Weeks!$A$7,$B10>Weeks!$B$59),"date outside this workbook's year",IF(AND($D10="Advance",N($L10)<0),"Warning: more than earned so far - worker now owes "&TEXT(ROUND(-$L10,0),"#,##0"),"")))))))))
A11: =IF($B11="","",ROW()-6) | I11: =IF($C11="","",IFERROR(INDEX(WorkerIDs,MATCH($C11,WorkerNames,0)),"?")) | J11: =IF($B11="","",$B11-WEEKDAY($B11,2)+1) | K11: =IF(OR($I11="",$I11="?",$D11<>"Advance",$B11=""),"",$I11&"|"&$J11&"|"&COUNTIFS($I$7:$I11,$I11,$J$7:$J11,$J11,$D$7:$D11,"Advance")) | L11: =IF(OR($I11="",$I11="?",$B11=""),"",SUMPRODUCT((Weeks!$A$7:$A$59<=$J11)*(Weeks!$X$5:$AI$5=$I11)*Weeks!$X$7:$AI$59)-SUMIFS($E$7:$E$1006,$I$7:$I$1006,$I11,$B$7:$B$1006,"<="&$B11)) | M11: =IF($B11&$C11&$D11&$E11="","",IF($B11="","missing date",IF($C11="","missing worker",IF($I11="?","unknown worker - was the name changed on Workers?",IF($D11="","missing type",IF(N($E11)=0,"missing amount",IF(AND($E11<0,$D11<>"Correction"),"negative amount - use a Correction to undo",IF(OR($B11<Weeks!$A$7,$B11>Weeks!$B$59),"date outside this workbook's year",IF(AND($D11="Advance",N($L11)<0),"Warning: more than earned so far - worker now owes "&TEXT(ROUND(-$L11,0),"#,##0"),"")))))))))
A12: =IF($B12="","",ROW()-6) | I12: =IF($C12="","",IFERROR(INDEX(WorkerIDs,MATCH($C12,WorkerNames,0)),"?")) | J12: =IF($B12="","",$B12-WEEKDAY($B12,2)+1) | K12: =IF(OR($I12="",$I12="?",$D12<>"Advance",$B12=""),"",$I12&"|"&$J12&"|"&COUNTIFS($I$7:$I12,$I12,$J$7:$J12,$J12,$D$7:$D12,"Advance")) | L12: =IF(OR($I12="",$I12="?",$B12=""),"",SUMPRODUCT((Weeks!$A$7:$A$59<=$J12)*(Weeks!$X$5:$AI$5=$I12)*Weeks!$X$7:$AI$59)-SUMIFS($E$7:$E$1006,$I$7:$I$1006,$I12,$B$7:$B$1006,"<="&$B12)) | M12: =IF($B12&$C12&$D12&$E12="","",IF($B12="","missing date",IF($C12="","missing worker",IF($I12="?","unknown worker - was the name changed on Workers?",IF($D12="","missing type",IF(N($E12)=0,"missing amount",IF(AND($E12<0,$D12<>"Correction"),"negative amount - use a Correction to undo",IF(OR($B12<Weeks!$A$7,$B12>Weeks!$B$59),"date outside this workbook's year",IF(AND($D12="Advance",N($L12)<0),"Warning: more than earned so far - worker now owes "&TEXT(ROUND(-$L12,0),"#,##0"),"")))))))))
A13: =IF($B13="","",ROW()-6) | I13: =IF($C13="","",IFERROR(INDEX(WorkerIDs,MATCH($C13,WorkerNames,0)),"?")) | J13: =IF($B13="","",$B13-WEEKDAY($B13,2)+1) | K13: =IF(OR($I13="",$I13="?",$D13<>"Advance",$B13=""),"",$I13&"|"&$J13&"|"&COUNTIFS($I$7:$I13,$I13,$J$7:$J13,$J13,$D$7:$D13,"Advance")) | L13: =IF(OR($I13="",$I13="?",$B13=""),"",SUMPRODUCT((Weeks!$A$7:$A$59<=$J13)*(Weeks!$X$5:$AI$5=$I13)*Weeks!$X$7:$AI$59)-SUMIFS($E$7:$E$1006,$I$7:$I$1006,$I13,$B$7:$B$1006,"<="&$B13)) | M13: =IF($B13&$C13&$D13&$E13="","",IF($B13="","missing date",IF($C13="","missing worker",IF($I13="?","unknown worker - was the name changed on Workers?",IF($D13="","missing type",IF(N($E13)=0,"missing amount",IF(AND($E13<0,$D13<>"Correction"),"negative amount - use a Correction to undo",IF(OR($B13<Weeks!$A$7,$B13>Weeks!$B$59),"date outside this workbook's year",IF(AND($D13="Advance",N($L13)<0),"Warning: more than earned so far - worker now owes "&TEXT(ROUND(-$L13,0),"#,##0"),"")))))))))
A14: =IF($B14="","",ROW()-6) | I14: =IF($C14="","",IFERROR(INDEX(WorkerIDs,MATCH($C14,WorkerNames,0)),"?")) | J14: =IF($B14="","",$B14-WEEKDAY($B14,2)+1) | K14: =IF(OR($I14="",$I14="?",$D14<>"Advance",$B14=""),"",$I14&"|"&$J14&"|"&COUNTIFS($I$7:$I14,$I14,$J$7:$J14,$J14,$D$7:$D14,"Advance")) | L14: =IF(OR($I14="",$I14="?",$B14=""),"",SUMPRODUCT((Weeks!$A$7:$A$59<=$J14)*(Weeks!$X$5:$AI$5=$I14)*Weeks!$X$7:$AI$59)-SUMIFS($E$7:$E$1006,$I$7:$I$1006,$I14,$B$7:$B$1006,"<="&$B14)) | M14: =IF($B14&$C14&$D14&$E14="","",IF($B14="","missing date",IF($C14="","missing worker",IF($I14="?","unknown worker - was the name changed on Workers?",IF($D14="","missing type",IF(N($E14)=0,"missing amount",IF(AND($E14<0,$D14<>"Correction"),"negative amount - use a Correction to undo",IF(OR($B14<Weeks!$A$7,$B14>Weeks!$B$59),"date outside this workbook's year",IF(AND($D14="Advance",N($L14)<0),"Warning: more than earned so far - worker now owes "&TEXT(ROUND(-$L14,0),"#,##0"),"")))))))))
A15: =IF($B15="","",ROW()-6) | I15: =IF($C15="","",IFERROR(INDEX(WorkerIDs,MATCH($C15,WorkerNames,0)),"?")) | J15: =IF($B15="","",$B15-WEEKDAY($B15,2)+1) | K15: =IF(OR($I15="",$I15="?",$D15<>"Advance",$B15=""),"",$I15&"|"&$J15&"|"&COUNTIFS($I$7:$I15,$I15,$J$7:$J15,$J15,$D$7:$D15,"Advance")) | L15: =IF(OR($I15="",$I15="?",$B15=""),"",SUMPRODUCT((Weeks!$A$7:$A$59<=$J15)*(Weeks!$X$5:$AI$5=$I15)*Weeks!$X$7:$AI$59)-SUMIFS($E$7:$E$1006,$I$7:$I$1006,$I15,$B$7:$B$1006,"<="&$B15)) | M15: =IF($B15&$C15&$D15&$E15="","",IF($B15="","missing date",IF($C15="","missing worker",IF($I15="?","unknown worker - was the name changed on Workers?",IF($D15="","missing type",IF(N($E15)=0,"missing amount",IF(AND($E15<0,$D15<>"Correction"),"negative amount - use a Correction to undo",IF(OR($B15<Weeks!$A$7,$B15>Weeks!$B$59),"date outside this workbook's year",IF(AND($D15="Advance",N($L15)<0),"Warning: more than earned so far - worker now owes "&TEXT(ROUND(-$L15,0),"#,##0"),"")))))))))
A16: =IF($B16="","",ROW()-6) | I16: =IF($C16="","",IFERROR(INDEX(WorkerIDs,MATCH($C16,WorkerNames,0)),"?")) | J16: =IF($B16="","",$B16-WEEKDAY($B16,2)+1) | K16: =IF(OR($I16="",$I16="?",$D16<>"Advance",$B16=""),"",$I16&"|"&$J16&"|"&COUNTIFS($I$7:$I16,$I16,$J$7:$J16,$J16,$D$7:$D16,"Advance")) | L16: =IF(OR($I16="",$I16="?",$B16=""),"",SUMPRODUCT((Weeks!$A$7:$A$59<=$J16)*(Weeks!$X$5:$AI$5=$I16)*Weeks!$X$7:$AI$59)-SUMIFS($E$7:$E$1006,$I$7:$I$1006,$I16,$B$7:$B$1006,"<="&$B16)) | M16: =IF($B16&$C16&$D16&$E16="","",IF($B16="","missing date",IF($C16="","missing worker",IF($I16="?","unknown worker - was the name changed on Workers?",IF($D16="","missing type",IF(N($E16)=0,"missing amount",IF(AND($E16<0,$D16<>"Correction"),"negative amount - use a Correction to undo",IF(OR($B16<Weeks!$A$7,$B16>Weeks!$B$59),"date outside this workbook's year",IF(AND($D16="Advance",N($L16)<0),"Warning: more than earned so far - worker now owes "&TEXT(ROUND(-$L16,0),"#,##0"),"")))))))))
A17: =IF($B17="","",ROW()-6) | I17: =IF($C17="","",IFERROR(INDEX(WorkerIDs,MATCH($C17,WorkerNames,0)),"?")) | J17: =IF($B17="","",$B17-WEEKDAY($B17,2)+1) | K17: =IF(OR($I17="",$I17="?",$D17<>"Advance",$B17=""),"",$I17&"|"&$J17&"|"&COUNTIFS($I$7:$I17,$I17,$J$7:$J17,$J17,$D$7:$D17,"Advance")) | L17: =IF(OR($I17="",$I17="?",$B17=""),"",SUMPRODUCT((Weeks!$A$7:$A$59<=$J17)*(Weeks!$X$5:$AI$5=$I17)*Weeks!$X$7:$AI$59)-SUMIFS($E$7:$E$1006,$I$7:$I$1006,$I17,$B$7:$B$1006,"<="&$B17)) | M17: =IF($B17&$C17&$D17&$E17="","",IF($B17="","missing date",IF($C17="","missing worker",IF($I17="?","unknown worker - was the name changed on Workers?",IF($D17="","missing type",IF(N($E17)=0,"missing amount",IF(AND($E17<0,$D17<>"Correction"),"negative amount - use a Correction to undo",IF(OR($B17<Weeks!$A$7,$B17>Weeks!$B$59),"date outside this workbook's year",IF(AND($D17="Advance",N($L17)<0),"Warning: more than earned so far - worker now owes "&TEXT(ROUND(-$L17,0),"#,##0"),"")))))))))
A18: =IF($B18="","",ROW()-6) | I18: =IF($C18="","",IFERROR(INDEX(WorkerIDs,MATCH($C18,WorkerNames,0)),"?")) | J18: =IF($B18="","",$B18-WEEKDAY($B18,2)+1) | K18: =IF(OR($I18="",$I18="?",$D18<>"Advance",$B18=""),"",$I18&"|"&$J18&"|"&COUNTIFS($I$7:$I18,$I18,$J$7:$J18,$J18,$D$7:$D18,"Advance")) | L18: =IF(OR($I18="",$I18="?",$B18=""),"",SUMPRODUCT((Weeks!$A$7:$A$59<=$J18)*(Weeks!$X$5:$AI$5=$I18)*Weeks!$X$7:$AI$59)-SUMIFS($E$7:$E$1006,$I$7:$I$1006,$I18,$B$7:$B$1006,"<="&$B18)) | M18: =IF($B18&$C18&$D18&$E18="","",IF($B18="","missing date",IF($C18="","missing worker",IF($I18="?","unknown worker - was the name changed on Workers?",IF($D18="","missing type",IF(N($E18)=0,"missing amount",IF(AND($E18<0,$D18<>"Correction"),"negative amount - use a Correction to undo",IF(OR($B18<Weeks!$A$7,$B18>Weeks!$B$59),"date outside this workbook's year",IF(AND($D18="Advance",N($L18)<0),"Warning: more than earned so far - worker now owes "&TEXT(ROUND(-$L18,0),"#,##0"),"")))))))))
A19: =IF($B19="","",ROW()-6) | I19: =IF($C19="","",IFERROR(INDEX(WorkerIDs,MATCH($C19,WorkerNames,0)),"?")) | J19: =IF($B19="","",$B19-WEEKDAY($B19,2)+1) | K19: =IF(OR($I19="",$I19="?",$D19<>"Advance",$B19=""),"",$I19&"|"&$J19&"|"&COUNTIFS($I$7:$I19,$I19,$J$7:$J19,$J19,$D$7:$D19,"Advance")) | L19: =IF(OR($I19="",$I19="?",$B19=""),"",SUMPRODUCT((Weeks!$A$7:$A$59<=$J19)*(Weeks!$X$5:$AI$5=$I19)*Weeks!$X$7:$AI$59)-SUMIFS($E$7:$E$1006,$I$7:$I$1006,$I19,$B$7:$B$1006,"<="&$B19)) | M19: =IF($B19&$C19&$D19&$E19="","",IF($B19="","missing date",IF($C19="","missing worker",IF($I19="?","unknown worker - was the name changed on Workers?",IF($D19="","missing type",IF(N($E19)=0,"missing amount",IF(AND($E19<0,$D19<>"Correction"),"negative amount - use a Correction to undo",IF(OR($B19<Weeks!$A$7,$B19>Weeks!$B$59),"date outside this workbook's year",IF(AND($D19="Advance",N($L19)<0),"Warning: more than earned so far - worker now owes "&TEXT(ROUND(-$L19,0),"#,##0"),"")))))))))
A20: =IF($B20="","",ROW()-6) | I20: =IF($C20="","",IFERROR(INDEX(WorkerIDs,MATCH($C20,WorkerNames,0)),"?")) | J20: =IF($B20="","",$B20-WEEKDAY($B20,2)+1) | K20: =IF(OR($I20="",$I20="?",$D20<>"Advance",$B20=""),"",$I20&"|"&$J20&"|"&COUNTIFS($I$7:$I20,$I20,$J$7:$J20,$J20,$D$7:$D20,"Advance")) | L20: =IF(OR($I20="",$I20="?",$B20=""),"",SUMPRODUCT((Weeks!$A$7:$A$59<=$J20)*(Weeks!$X$5:$AI$5=$I20)*Weeks!$X$7:$AI$59)-SUMIFS($E$7:$E$1006,$I$7:$I$1006,$I20,$B$7:$B$1006,"<="&$B20)) | M20: =IF($B20&$C20&$D20&$E20="","",IF($B20="","missing date",IF($C20="","missing worker",IF($I20="?","unknown worker - was the name changed on Workers?",IF($D20="","missing type",IF(N($E20)=0,"missing amount",IF(AND($E20<0,$D20<>"Correction"),"negative amount - use a Correction to undo",IF(OR($B20<Weeks!$A$7,$B20>Weeks!$B$59),"date outside this workbook's year",IF(AND($D20="Advance",N($L20)<0),"Warning: more than earned so far - worker now owes "&TEXT(ROUND(-$L20,0),"#,##0"),"")))))))))
... A1006: =IF($B1006="","",ROW()-6) | I1006: =IF($C1006="","",IFERROR(INDEX(WorkerIDs,MATCH($C1006,WorkerNames,0)),"?")) | J1006: =IF($B1006="","",$B1006-WEEKDAY($B1006,2)+1) | K1006: =IF(OR($I1006="",$I1006="?",$D1006<>"Advance",$B1006=""),"",$I1006&"|"&$J1006&"|"&COUNTIFS($I$7:$I1006,$I1006,$J$7:$J1006,$J1006,$D$7:$D1006,"Advance")) | L1006: =IF(OR($I1006="",$I1006="?",$B1006=""),"",SUMPRODUCT((Weeks!$A$7:$A$59<=$J1006)*(Weeks!$X$5:$AI$5=$I1006)*Weeks!$X$7:$AI$59)-SUMIFS($E$7:$E$1006,$I$7:$I$1006,$I1006,$B$7:$B$1006,"<="&$B1006)) | M1006: =IF($B1006&$C1006&$D1006&$E1006="","",IF($B1006="","missing date",IF($C1006="","missing worker",IF($I1006="?","unknown worker - was the name changed on Workers?",IF($D1006="","missing type",IF(N($E1006)=0,"missing amount",IF(AND($E1006<0,$D1006<>"Correction"),"negative amount - use a Correction to undo",IF(OR($B1006<Weeks!$A$7,$B1006>Weeks!$B$59),"date outside this workbook's year",IF(AND($D1006="Advance",N($L1006)<0),"Warning: more than earned so far - worker now owes "&TEXT(ROUND(-$L1006,0),"#,##0"),"")))))))))

Sheet Weekly Pay
A1: ◆ Donabay | C1: Home | D1: Daily Log | F1: Cash Ledger | H1: Weekly Pay | J1: Payslip | L1: Workers | N1: Settings | P1: Guide | R1: · | S1: History | U1: Weeks | X1: Checks
A2: Weekly Pay
A3: Payday. Pick the week, pay each worker the green TO PAY column, then copy the 'Ready for the Cash Ledger' list on the right into the Cash Ledger (Paste Values).
B5: Week starting (Monday): | C5: 46286 | D5: =$C$5+6 -> 46292
B7: Good blocks | D7: Paid blocks | F7: Pot (so'm) | H7: Crew-days | J7: Reject rate | L7: Workbook checks
B8: =IFERROR(INDEX(Weeks!$E$7:$E$59,MATCH($C$5,Weeks!$A$7:$A$59,0)),0) -> 11857 | D8: =IFERROR(INDEX(Weeks!$F$7:$F$59,MATCH($C$5,Weeks!$A$7:$A$59,0)),0) -> 11857 | F8: =IFERROR(INDEX(Weeks!$G$7:$G$59,MATCH($C$5,Weeks!$A$7:$A$59,0)),0) -> 5928500 | H8: =IFERROR(INDEX(Weeks!$H$7:$H$59,MATCH($C$5,Weeks!$A$7:$A$59,0)),0) -> 24 | J8: =IFERROR(INDEX(Weeks!$I$7:$I$59,MATCH($C$5,Weeks!$A$7:$A$59,0)),0) -> 0.010101853 | L8: =Checks!$C$5 -> ALL CHECKS OK | Q8: Ready for the Cash Ledger
Q9: After paying: select the filled rows below, copy, go to the next empty row in the Cash Ledger (column B) and Paste Values (Ctrl+Shift+V, or Paste ▸ Values).
A11: ID | B11: Worker | C11: Status | D11: Days | E11: Share | F11: Earned this week | G11: Brought forward | H11: Advances | I11: Corrections | J11: Due | K11: TO PAY | L11: Paid (in ledger) | M11: Still to pay | N11: Carried forward | O11: Note | Q11: Date | R11: Worker | S11: Type | T11: Amount (so'm) | U11: slot
A12: =Workers!$A$6 -> W01 | B12: =IF(Workers!$B$6="","",Workers!$B$6) -> Davlatbek | C12: =IF($B12="","",Workers!$C$6) -> Active | D12: =IF($B12="","",IFERROR(INDEX(Weeks!$L$7:$W$59,MATCH($C$5,Weeks!$A$7:$A$59,0),MATCH($A12,Weeks!$L$5:$W$5,0)),0)) -> 6 | E12: =IF(OR($B12="",N($H$8)=0),"",$D12/$H$8) -> 0.25 | F12: =IF($B12="","",IFERROR(INDEX(Weeks!$X$7:$AI$59,MATCH($C$5,Weeks!$A$7:$A$59,0),MATCH($A12,Weeks!$X$5:$AI$5,0)),0)) -> 1482125 | G12: =IF($B12="","",SUMPRODUCT((Weeks!$A$7:$A$59<$C$5)*(Weeks!$X$5:$AI$5=$A12)*Weeks!$X$7:$AI$59)-SUMIFS('Cash Ledger'!$E$7:$E$1006,'Cash Ledger'!$I$7:$I$1006,$A12,'Cash Ledger'!$B$7:$B$1006,"<"&$C$5)) -> 0 | H12: =IF($B12="","",SUMIFS('Cash Ledger'!$E$7:$E$1006,'Cash Ledger'!$I$7:$I$1006,$A12,'Cash Ledger'!$D$7:$D$1006,"Advance",'Cash Ledger'!$B$7:$B$1006,">="&$C$5,'Cash Ledger'!$B$7:$B$1006,"<="&($C$5+6))) -> 150000 | I12: =IF($B12="","",SUMIFS('Cash Ledger'!$E$7:$E$1006,'Cash Ledger'!$I$7:$I$1006,$A12,'Cash Ledger'!$D$7:$D$1006,"Correction",'Cash Ledger'!$B$7:$B$1006,">="&$C$5,'Cash Ledger'!$B$7:$B$1006,"<="&($C$5+6))) -> 0 | J12: =IF($B12="","",$G12+$F12-$H12-$I12) -> 1332125 | K12: =IF($B12="","",ROUND(MAX(0,IF($G12>=0,$J12,$F12-$H12-$I12-MIN(-$G12,DebtCap*$F12))),0)) -> 1332125 | L12: =IF($B12="","",SUMIFS('Cash Ledger'!$E$7:$E$1006,'Cash Ledger'!$I$7:$I$1006,$A12,'Cash Ledger'!$D$7:$D$1006,"Weekly pay",'Cash Ledger'!$B$7:$B$1006,">="&$C$5,'Cash Ledger'!$B$7:$B$1006,"<="&($C$5+6))) -> 0 | M12: =IF($B12="","",MAX(0,$K12-$L12)) -> 1332125 | N12: =IF($B12="","",$J12-$L12) -> 1332125 | O12: =IF($B12="","",IF(ROUND($N12,0)<0,"owes you "&TEXT(ROUND(-$N12,0),"#,##0"),IF(AND(ROUND($N12,0)>0,$M12>0),"not yet paid",IF(ROUND($N12,0)>0,"you owe "&TEXT(ROUND($N12,0),"#,##0"),"settled")))) -> not yet paid | Q12: =IF($U12="","",MEDIAN($C$5,$C$5+6,TODAY())) -> 46289 | R12: {=IF($U12="","",INDEX($B$12:$B$23,$U12))} -> Davlatbek | S12: =IF($U12="","","Weekly pay") -> Weekly pay | T12: {=IF($U12="","",INDEX($M$12:$M$23,$U12))} -> 1332125 | U12: {=IFERROR(_xlfn.AGGREGATE(15,6,(ROW($M$12:$M$23)-ROW($M$12)+1)/(ISNUMBER($M$12:$M$23)*($M$12:$M$23>0)),ROWS($U$12:U12)),"")} -> 1
A13: =Workers!$A$7 -> W02 | B13: =IF(Workers!$B$7="","",Workers!$B$7) -> Xusanboy | C13: =IF($B13="","",Workers!$C$7) -> Active | D13: =IF($B13="","",IFERROR(INDEX(Weeks!$L$7:$W$59,MATCH($C$5,Weeks!$A$7:$A$59,0),MATCH($A13,Weeks!$L$5:$W$5,0)),0)) -> 6 | E13: =IF(OR($B13="",N($H$8)=0),"",$D13/$H$8) -> 0.25 | F13: =IF($B13="","",IFERROR(INDEX(Weeks!$X$7:$AI$59,MATCH($C$5,Weeks!$A$7:$A$59,0),MATCH($A13,Weeks!$X$5:$AI$5,0)),0)) -> 1482125 | G13: =IF($B13="","",SUMPRODUCT((Weeks!$A$7:$A$59<$C$5)*(Weeks!$X$5:$AI$5=$A13)*Weeks!$X$7:$AI$59)-SUMIFS('Cash Ledger'!$E$7:$E$1006,'Cash Ledger'!$I$7:$I$1006,$A13,'Cash Ledger'!$B$7:$B$1006,"<"&$C$5)) -> 0 | H13: =IF($B13="","",SUMIFS('Cash Ledger'!$E$7:$E$1006,'Cash Ledger'!$I$7:$I$1006,$A13,'Cash Ledger'!$D$7:$D$1006,"Advance",'Cash Ledger'!$B$7:$B$1006,">="&$C$5,'Cash Ledger'!$B$7:$B$1006,"<="&($C$5+6))) -> 500000 | I13: =IF($B13="","",SUMIFS('Cash Ledger'!$E$7:$E$1006,'Cash Ledger'!$I$7:$I$1006,$A13,'Cash Ledger'!$D$7:$D$1006,"Correction",'Cash Ledger'!$B$7:$B$1006,">="&$C$5,'Cash Ledger'!$B$7:$B$1006,"<="&($C$5+6))) -> 0 | J13: =IF($B13="","",$G13+$F13-$H13-$I13) -> 982125 | K13: =IF($B13="","",ROUND(MAX(0,IF($G13>=0,$J13,$F13-$H13-$I13-MIN(-$G13,DebtCap*$F13))),0)) -> 982125 | L13: =IF($B13="","",SUMIFS('Cash Ledger'!$E$7:$E$1006,'Cash Ledger'!$I$7:$I$1006,$A13,'Cash Ledger'!$D$7:$D$1006,"Weekly pay",'Cash Ledger'!$B$7:$B$1006,">="&$C$5,'Cash Ledger'!$B$7:$B$1006,"<="&($C$5+6))) -> 0 | M13: =IF($B13="","",MAX(0,$K13-$L13)) -> 982125 | N13: =IF($B13="","",$J13-$L13) -> 982125 | O13: =IF($B13="","",IF(ROUND($N13,0)<0,"owes you "&TEXT(ROUND(-$N13,0),"#,##0"),IF(AND(ROUND($N13,0)>0,$M13>0),"not yet paid",IF(ROUND($N13,0)>0,"you owe "&TEXT(ROUND($N13,0),"#,##0"),"settled")))) -> not yet paid | Q13: =IF($U13="","",MEDIAN($C$5,$C$5+6,TODAY())) -> 46289 | R13: {=IF($U13="","",INDEX($B$12:$B$23,$U13))} -> Xusanboy | S13: =IF($U13="","","Weekly pay") -> Weekly pay | T13: {=IF($U13="","",INDEX($M$12:$M$23,$U13))} -> 982125 | U13: {=IFERROR(_xlfn.AGGREGATE(15,6,(ROW($M$12:$M$23)-ROW($M$12)+1)/(ISNUMBER($M$12:$M$23)*($M$12:$M$23>0)),ROWS($U$12:U13)),"")} -> 2
A14: =Workers!$A$8 -> W03 | B14: =IF(Workers!$B$8="","",Workers!$B$8) -> Oybek | C14: =IF($B14="","",Workers!$C$8) -> Active | D14: =IF($B14="","",IFERROR(INDEX(Weeks!$L$7:$W$59,MATCH($C$5,Weeks!$A$7:$A$59,0),MATCH($A14,Weeks!$L$5:$W$5,0)),0)) -> 6 | E14: =IF(OR($B14="",N($H$8)=0),"",$D14/$H$8) -> 0.25 | F14: =IF($B14="","",IFERROR(INDEX(Weeks!$X$7:$AI$59,MATCH($C$5,Weeks!$A$7:$A$59,0),MATCH($A14,Weeks!$X$5:$AI$5,0)),0)) -> 1482125 | G14: =IF($B14="","",SUMPRODUCT((Weeks!$A$7:$A$59<$C$5)*(Weeks!$X$5:$AI$5=$A14)*Weeks!$X$7:$AI$59)-SUMIFS('Cash Ledger'!$E$7:$E$1006,'Cash Ledger'!$I$7:$I$1006,$A14,'Cash Ledger'!$B$7:$B$1006,"<"&$C$5)) -> 0 | H14: =IF($B14="","",SUMIFS('Cash Ledger'!$E$7:$E$1006,'Cash Ledger'!$I$7:$I$1006,$A14,'Cash Ledger'!$D$7:$D$1006,"Advance",'Cash Ledger'!$B$7:$B$1006,">="&$C$5,'Cash Ledger'!$B$7:$B$1006,"<="&($C$5+6))) -> 0 | I14: =IF($B14="","",SUMIFS('Cash Ledger'!$E$7:$E$1006,'Cash Ledger'!$I$7:$I$1006,$A14,'Cash Ledger'!$D$7:$D$1006,"Correction",'Cash Ledger'!$B$7:$B$1006,">="&$C$5,'Cash Ledger'!$B$7:$B$1006,"<="&($C$5+6))) -> 0 | J14: =IF($B14="","",$G14+$F14-$H14-$I14) -> 1482125 | K14: =IF($B14="","",ROUND(MAX(0,IF($G14>=0,$J14,$F14-$H14-$I14-MIN(-$G14,DebtCap*$F14))),0)) -> 1482125 | L14: =IF($B14="","",SUMIFS('Cash Ledger'!$E$7:$E$1006,'Cash Ledger'!$I$7:$I$1006,$A14,'Cash Ledger'!$D$7:$D$1006,"Weekly pay",'Cash Ledger'!$B$7:$B$1006,">="&$C$5,'Cash Ledger'!$B$7:$B$1006,"<="&($C$5+6))) -> 0 | M14: =IF($B14="","",MAX(0,$K14-$L14)) -> 1482125 | N14: =IF($B14="","",$J14-$L14) -> 1482125 | O14: =IF($B14="","",IF(ROUND($N14,0)<0,"owes you "&TEXT(ROUND(-$N14,0),"#,##0"),IF(AND(ROUND($N14,0)>0,$M14>0),"not yet paid",IF(ROUND($N14,0)>0,"you owe "&TEXT(ROUND($N14,0),"#,##0"),"settled")))) -> not yet paid | Q14: =IF($U14="","",MEDIAN($C$5,$C$5+6,TODAY())) -> 46289 | R14: {=IF($U14="","",INDEX($B$12:$B$23,$U14))} -> Oybek | S14: =IF($U14="","","Weekly pay") -> Weekly pay | T14: {=IF($U14="","",INDEX($M$12:$M$23,$U14))} -> 1482125 | U14: {=IFERROR(_xlfn.AGGREGATE(15,6,(ROW($M$12:$M$23)-ROW($M$12)+1)/(ISNUMBER($M$12:$M$23)*($M$12:$M$23>0)),ROWS($U$12:U14)),"")} -> 3
A15: =Workers!$A$9 -> W04 | B15: =IF(Workers!$B$9="","",Workers!$B$9) -> Abdurashid | C15: =IF($B15="","",Workers!$C$9) -> Active | D15: =IF($B15="","",IFERROR(INDEX(Weeks!$L$7:$W$59,MATCH($C$5,Weeks!$A$7:$A$59,0),MATCH($A15,Weeks!$L$5:$W$5,0)),0)) -> 6 | E15: =IF(OR($B15="",N($H$8)=0),"",$D15/$H$8) -> 0.25 | F15: =IF($B15="","",IFERROR(INDEX(Weeks!$X$7:$AI$59,MATCH($C$5,Weeks!$A$7:$A$59,0),MATCH($A15,Weeks!$X$5:$AI$5,0)),0)) -> 1482125 | G15: =IF($B15="","",SUMPRODUCT((Weeks!$A$7:$A$59<$C$5)*(Weeks!$X$5:$AI$5=$A15)*Weeks!$X$7:$AI$59)-SUMIFS('Cash Ledger'!$E$7:$E$1006,'Cash Ledger'!$I$7:$I$1006,$A15,'Cash Ledger'!$B$7:$B$1006,"<"&$C$5)) -> 0 | H15: =IF($B15="","",SUMIFS('Cash Ledger'!$E$7:$E$1006,'Cash Ledger'!$I$7:$I$1006,$A15,'Cash Ledger'!$D$7:$D$1006,"Advance",'Cash Ledger'!$B$7:$B$1006,">="&$C$5,'Cash Ledger'!$B$7:$B$1006,"<="&($C$5+6))) -> 0 | I15: =IF($B15="","",SUMIFS('Cash Ledger'!$E$7:$E$1006,'Cash Ledger'!$I$7:$I$1006,$A15,'Cash Ledger'!$D$7:$D$1006,"Correction",'Cash Ledger'!$B$7:$B$1006,">="&$C$5,'Cash Ledger'!$B$7:$B$1006,"<="&($C$5+6))) -> 0 | J15: =IF($B15="","",$G15+$F15-$H15-$I15) -> 1482125 | K15: =IF($B15="","",ROUND(MAX(0,IF($G15>=0,$J15,$F15-$H15-$I15-MIN(-$G15,DebtCap*$F15))),0)) -> 1482125 | L15: =IF($B15="","",SUMIFS('Cash Ledger'!$E$7:$E$1006,'Cash Ledger'!$I$7:$I$1006,$A15,'Cash Ledger'!$D$7:$D$1006,"Weekly pay",'Cash Ledger'!$B$7:$B$1006,">="&$C$5,'Cash Ledger'!$B$7:$B$1006,"<="&($C$5+6))) -> 0 | M15: =IF($B15="","",MAX(0,$K15-$L15)) -> 1482125 | N15: =IF($B15="","",$J15-$L15) -> 1482125 | O15: =IF($B15="","",IF(ROUND($N15,0)<0,"owes you "&TEXT(ROUND(-$N15,0),"#,##0"),IF(AND(ROUND($N15,0)>0,$M15>0),"not yet paid",IF(ROUND($N15,0)>0,"you owe "&TEXT(ROUND($N15,0),"#,##0"),"settled")))) -> not yet paid | Q15: =IF($U15="","",MEDIAN($C$5,$C$5+6,TODAY())) -> 46289 | R15: {=IF($U15="","",INDEX($B$12:$B$23,$U15))} -> Abdurashid | S15: =IF($U15="","","Weekly pay") -> Weekly pay | T15: {=IF($U15="","",INDEX($M$12:$M$23,$U15))} -> 1482125 | U15: {=IFERROR(_xlfn.AGGREGATE(15,6,(ROW($M$12:$M$23)-ROW($M$12)+1)/(ISNUMBER($M$12:$M$23)*($M$12:$M$23>0)),ROWS($U$12:U15)),"")} -> 4
A16: =Workers!$A$10 -> W05 | B16: =IF(Workers!$B$10="","",Workers!$B$10) | C16: =IF($B16="","",Workers!$C$10) | D16: =IF($B16="","",IFERROR(INDEX(Weeks!$L$7:$W$59,MATCH($C$5,Weeks!$A$7:$A$59,0),MATCH($A16,Weeks!$L$5:$W$5,0)),0)) | E16: =IF(OR($B16="",N($H$8)=0),"",$D16/$H$8) | F16: =IF($B16="","",IFERROR(INDEX(Weeks!$X$7:$AI$59,MATCH($C$5,Weeks!$A$7:$A$59,0),MATCH($A16,Weeks!$X$5:$AI$5,0)),0)) | G16: =IF($B16="","",SUMPRODUCT((Weeks!$A$7:$A$59<$C$5)*(Weeks!$X$5:$AI$5=$A16)*Weeks!$X$7:$AI$59)-SUMIFS('Cash Ledger'!$E$7:$E$1006,'Cash Ledger'!$I$7:$I$1006,$A16,'Cash Ledger'!$B$7:$B$1006,"<"&$C$5)) | H16: =IF($B16="","",SUMIFS('Cash Ledger'!$E$7:$E$1006,'Cash Ledger'!$I$7:$I$1006,$A16,'Cash Ledger'!$D$7:$D$1006,"Advance",'Cash Ledger'!$B$7:$B$1006,">="&$C$5,'Cash Ledger'!$B$7:$B$1006,"<="&($C$5+6))) | I16: =IF($B16="","",SUMIFS('Cash Ledger'!$E$7:$E$1006,'Cash Ledger'!$I$7:$I$1006,$A16,'Cash Ledger'!$D$7:$D$1006,"Correction",'Cash Ledger'!$B$7:$B$1006,">="&$C$5,'Cash Ledger'!$B$7:$B$1006,"<="&($C$5+6))) | J16: =IF($B16="","",$G16+$F16-$H16-$I16) | K16: =IF($B16="","",ROUND(MAX(0,IF($G16>=0,$J16,$F16-$H16-$I16-MIN(-$G16,DebtCap*$F16))),0)) | L16: =IF($B16="","",SUMIFS('Cash Ledger'!$E$7:$E$1006,'Cash Ledger'!$I$7:$I$1006,$A16,'Cash Ledger'!$D$7:$D$1006,"Weekly pay",'Cash Ledger'!$B$7:$B$1006,">="&$C$5,'Cash Ledger'!$B$7:$B$1006,"<="&($C$5+6))) | M16: =IF($B16="","",MAX(0,$K16-$L16)) | N16: =IF($B16="","",$J16-$L16) | O16: =IF($B16="","",IF(ROUND($N16,0)<0,"owes you "&TEXT(ROUND(-$N16,0),"#,##0"),IF(AND(ROUND($N16,0)>0,$M16>0),"not yet paid",IF(ROUND($N16,0)>0,"you owe "&TEXT(ROUND($N16,0),"#,##0"),"settled")))) | Q16: =IF($U16="","",MEDIAN($C$5,$C$5+6,TODAY())) | R16: {=IF($U16="","",INDEX($B$12:$B$23,$U16))} | S16: =IF($U16="","","Weekly pay") | T16: {=IF($U16="","",INDEX($M$12:$M$23,$U16))} | U16: {=IFERROR(_xlfn.AGGREGATE(15,6,(ROW($M$12:$M$23)-ROW($M$12)+1)/(ISNUMBER($M$12:$M$23)*($M$12:$M$23>0)),ROWS($U$12:U16)),"")}
